[2024-12-11 17:50:30,687: INFO: etl_main: >>>>>>> stage Data Extraction Stage started <<<<<<<<]
[2024-12-11 17:50:30,694: INFO: common: yaml file: D:\repositories\coustomer churn prediction\config\etl_config.yaml loaded successfully]
[2024-12-11 17:50:30,694: ERROR: etl_main: "'ConfigBox' object has no attribute 'artifacts_root'"]
Traceback (most recent call last):
  File "box\\box.py", line 593, in box.box.Box.__getitem__
KeyError: 'artifacts_root'

The above exception was the direct cause of the following exception:

Traceback (most recent call last):
  File "box\\box.py", line 632, in box.box.Box.__getattr__
  File "box\\box.py", line 620, in box.box.Box.__getitem__
box.exceptions.BoxKeyError: "'artifacts_root'"

During handling of the above exception, another exception occurred:

Traceback (most recent call last):
  File "box\\box.py", line 634, in box.box.Box.__getattr__
AttributeError: 'ConfigBox' object has no attribute 'artifacts_root'

The above exception was the direct cause of the following exception:

Traceback (most recent call last):
  File "box\\config_box.py", line 29, in box.config_box.ConfigBox.__getattr__
  File "box\\box.py", line 648, in box.box.Box.__getattr__
box.exceptions.BoxKeyError: "'ConfigBox' object has no attribute 'artifacts_root'"

During handling of the above exception, another exception occurred:

Traceback (most recent call last):
  File "box\\box.py", line 593, in box.box.Box.__getitem__
KeyError: 'artifacts_root'

The above exception was the direct cause of the following exception:

Traceback (most recent call last):
  File "box\\box.py", line 632, in box.box.Box.__getattr__
  File "box\\box.py", line 620, in box.box.Box.__getitem__
box.exceptions.BoxKeyError: "'artifacts_root'"

During handling of the above exception, another exception occurred:

Traceback (most recent call last):
  File "box\\box.py", line 634, in box.box.Box.__getattr__
AttributeError: 'ConfigBox' object has no attribute 'artifacts_root'

The above exception was the direct cause of the following exception:

Traceback (most recent call last):
  File "D:\repositories\coustomer churn prediction\etl_main.py", line 8, in <module>
    data_extraction.initiate_data_extraction()
  File "D:\repositories\coustomer churn prediction\src\churn_etl\pipeline\data_extraction_pipeline.py", line 17, in initiate_data_extraction
    raise e
  File "D:\repositories\coustomer churn prediction\src\churn_etl\pipeline\data_extraction_pipeline.py", line 11, in initiate_data_extraction
    config = ETLConfigurationManager()
  File "D:\repositories\coustomer churn prediction\src\churn_etl\config\configuration.py", line 11, in __init__
    create_directories([self.config.artifacts_root])
  File "box\\config_box.py", line 31, in box.config_box.ConfigBox.__getattr__
  File "box\\box.py", line 648, in box.box.Box.__getattr__
box.exceptions.BoxKeyError: "'ConfigBox' object has no attribute 'artifacts_root'"
[2024-12-11 17:51:08,592: INFO: etl_main: >>>>>>> stage Data Extraction Stage started <<<<<<<<]
[2024-12-11 17:51:08,596: INFO: common: yaml file: D:\repositories\coustomer churn prediction\config\etl_config.yaml loaded successfully]
[2024-12-11 17:51:08,597: INFO: common: Directory ETL_artifacts created successfully]
[2024-12-11 17:51:08,612: INFO: common: Directory artifacts/data_Extracting created successfully]
[2024-12-11 17:51:08,612: ERROR: etl_main: DataExtractingArtifact.__init__() missing 2 required positional arguments: 'data_loading_status' and 'loaded_data_frame']
Traceback (most recent call last):
  File "D:\repositories\coustomer churn prediction\etl_main.py", line 8, in <module>
    data_extraction.initiate_data_extraction()
  File "D:\repositories\coustomer churn prediction\src\churn_etl\pipeline\data_extraction_pipeline.py", line 17, in initiate_data_extraction
    raise e
  File "D:\repositories\coustomer churn prediction\src\churn_etl\pipeline\data_extraction_pipeline.py", line 13, in initiate_data_extraction
    data_loader = DataExtractor(config=data_loading_config)
  File "D:\repositories\coustomer churn prediction\src\churn_etl\components\data_extracting.py", line 12, in __init__
    self.artifact = DataExtractingArtifact()
TypeError: DataExtractingArtifact.__init__() missing 2 required positional arguments: 'data_loading_status' and 'loaded_data_frame'
[2024-12-11 17:55:35,901: INFO: etl_main: >>>>>>> stage Data Extraction Stage started <<<<<<<<]
[2024-12-11 17:55:35,903: INFO: common: yaml file: D:\repositories\coustomer churn prediction\config\etl_config.yaml loaded successfully]
[2024-12-11 17:55:35,903: INFO: common: Directory ETL_artifacts created successfully]
[2024-12-11 17:55:35,903: INFO: common: Directory artifacts/data_Extracting created successfully]
[2024-12-11 17:55:35,903: ERROR: etl_main: 'DataExtractor' object has no attribute 'load_from_postgresSQL']
Traceback (most recent call last):
  File "D:\repositories\coustomer churn prediction\etl_main.py", line 8, in <module>
    data_extraction.initiate_data_extraction()
  File "D:\repositories\coustomer churn prediction\src\churn_etl\pipeline\data_extraction_pipeline.py", line 17, in initiate_data_extraction
    raise e
  File "D:\repositories\coustomer churn prediction\src\churn_etl\pipeline\data_extraction_pipeline.py", line 14, in initiate_data_extraction
    data_extractor_artifact = data_extractor.load_from_postgresSQL()
AttributeError: 'DataExtractor' object has no attribute 'load_from_postgresSQL'
[2024-12-11 17:56:06,330: INFO: etl_main: >>>>>>> stage Data Extraction Stage started <<<<<<<<]
[2024-12-11 17:56:06,330: INFO: common: yaml file: D:\repositories\coustomer churn prediction\config\etl_config.yaml loaded successfully]
[2024-12-11 17:56:06,342: INFO: common: Directory ETL_artifacts created successfully]
[2024-12-11 17:56:06,342: INFO: common: Directory artifacts/data_Extracting created successfully]
[2024-12-11 17:56:12,068: ERROR: etl_main: 'NoneType' object has no attribute 'loaded_data_frame']
Traceback (most recent call last):
  File "D:\repositories\coustomer churn prediction\etl_main.py", line 8, in <module>
    data_extraction.initiate_data_extraction()
  File "D:\repositories\coustomer churn prediction\src\churn_etl\pipeline\data_extraction_pipeline.py", line 17, in initiate_data_extraction
    raise e
  File "D:\repositories\coustomer churn prediction\src\churn_etl\pipeline\data_extraction_pipeline.py", line 15, in initiate_data_extraction
    print(data_extractor_artifact.loaded_data_frame.head())
AttributeError: 'NoneType' object has no attribute 'loaded_data_frame'
[2024-12-11 18:10:23,749: INFO: etl_main: >>>>>>> stage Data Extraction Stage started <<<<<<<<]
[2024-12-11 18:10:23,750: INFO: common: yaml file: D:\repositories\coustomer churn prediction\config\etl_config.yaml loaded successfully]
[2024-12-11 18:10:23,751: INFO: common: Directory ETL_artifacts created successfully]
[2024-12-11 18:10:23,751: INFO: common: Directory artifacts/data_Extracting created successfully]
[2024-12-11 18:10:30,935: INFO: data_extracting: data succesfully fetched from customer_churn_data and table customers]
[2024-12-11 18:10:30,964: INFO: etl_main: >>>>>>> stage Data Extraction Stage completed <<<<<<<<

=================x]
[2024-12-11 19:02:37,699: INFO: etl_main: >>>>>>> stage Data Extraction Stage started <<<<<<<<]
[2024-12-11 19:02:37,701: INFO: common: yaml file: D:\repositories\coustomer churn prediction\config\etl_config.yaml loaded successfully]
[2024-12-11 19:02:37,701: INFO: common: Directory ETL_artifacts created successfully]
[2024-12-11 19:02:37,701: INFO: common: Directory artifacts/data_Extracting created successfully]
[2024-12-11 19:02:43,750: INFO: data_extracting: data succesfully fetched from customer_churn_data and table customers]
[2024-12-11 19:02:43,750: INFO: etl_main: >>>>>>> stage Data Extraction Stage completed <<<<<<<<

=================x]
[2024-12-11 19:02:43,750: INFO: etl_main: >>>>>>> stage Data Transformation Stage started <<<<<<<<]
[2024-12-11 19:02:43,753: INFO: common: yaml file: D:\repositories\coustomer churn prediction\config\etl_config.yaml loaded successfully]
[2024-12-11 19:02:43,753: INFO: common: Directory ETL_artifacts created successfully]
[2024-12-11 19:02:43,753: INFO: common: Directory artifacts/data_transformation created successfully]
[2024-12-11 19:02:43,753: ERROR: etl_main: "'ConfigBox' object has no attribute 'customerid'"]
Traceback (most recent call last):
  File "box\\box.py", line 593, in box.box.Box.__getitem__
KeyError: 'CustomerID'

The above exception was the direct cause of the following exception:

Traceback (most recent call last):
  File "box\\box.py", line 632, in box.box.Box.__getattr__
  File "box\\box.py", line 620, in box.box.Box.__getitem__
box.exceptions.BoxKeyError: "'CustomerID'"

During handling of the above exception, another exception occurred:

Traceback (most recent call last):
  File "box\\box.py", line 634, in box.box.Box.__getattr__
AttributeError: 'ConfigBox' object has no attribute 'CustomerID'

The above exception was the direct cause of the following exception:

Traceback (most recent call last):
  File "box\\config_box.py", line 29, in box.config_box.ConfigBox.__getattr__
  File "box\\box.py", line 648, in box.box.Box.__getattr__
box.exceptions.BoxKeyError: "'ConfigBox' object has no attribute 'CustomerID'"

During handling of the above exception, another exception occurred:

Traceback (most recent call last):
  File "box\\box.py", line 593, in box.box.Box.__getitem__
KeyError: 'customerid'

The above exception was the direct cause of the following exception:

Traceback (most recent call last):
  File "box\\box.py", line 632, in box.box.Box.__getattr__
  File "box\\box.py", line 620, in box.box.Box.__getitem__
box.exceptions.BoxKeyError: "'customerid'"

During handling of the above exception, another exception occurred:

Traceback (most recent call last):
  File "box\\box.py", line 634, in box.box.Box.__getattr__
AttributeError: 'ConfigBox' object has no attribute 'customerid'

The above exception was the direct cause of the following exception:

Traceback (most recent call last):
  File "D:\repositories\coustomer churn prediction\etl_main.py", line 19, in <module>
    data_transformation.initiate_data_Transformation()
  File "D:\repositories\coustomer churn prediction\src\churn_etl\pipeline\data_transformation_pipeline.py", line 17, in initiate_data_Transformation
    raise e
  File "D:\repositories\coustomer churn prediction\src\churn_etl\pipeline\data_transformation_pipeline.py", line 13, in initiate_data_Transformation
    data_Transformation_config = config.get_data_transformation_config()
  File "D:\repositories\coustomer churn prediction\src\churn_etl\config\configuration.py", line 43, in get_data_transformation_config
    "CustomerID": str(config.CustomerID),
  File "box\\config_box.py", line 31, in box.config_box.ConfigBox.__getattr__
  File "box\\box.py", line 648, in box.box.Box.__getattr__
box.exceptions.BoxKeyError: "'ConfigBox' object has no attribute 'customerid'"
[2024-12-11 19:17:16,942: INFO: etl_main: >>>>>>> stage Data Extraction Stage started <<<<<<<<]
[2024-12-11 19:17:16,945: INFO: common: yaml file: D:\repositories\coustomer churn prediction\config\etl_config.yaml loaded successfully]
[2024-12-11 19:17:16,945: INFO: common: Directory ETL_artifacts created successfully]
[2024-12-11 19:17:16,946: INFO: common: Directory artifacts/data_Extracting created successfully]
[2024-12-11 19:17:23,060: INFO: data_extracting: data succesfully fetched from customer_churn_data and table customers]
[2024-12-11 19:17:23,060: INFO: etl_main: >>>>>>> stage Data Extraction Stage completed <<<<<<<<

=================x]
[2024-12-11 19:17:23,060: INFO: etl_main: >>>>>>> stage Data Transformation Stage started <<<<<<<<]
[2024-12-11 19:17:23,060: INFO: common: yaml file: D:\repositories\coustomer churn prediction\config\etl_config.yaml loaded successfully]
[2024-12-11 19:17:23,060: INFO: common: Directory ETL_artifacts created successfully]
[2024-12-11 19:17:23,060: INFO: common: Directory artifacts/data_transformation created successfully]
[2024-12-11 19:17:23,060: ERROR: etl_main: "'ConfigBox' object has no attribute 'customerid'"]
Traceback (most recent call last):
  File "box\\box.py", line 593, in box.box.Box.__getitem__
KeyError: 'CustomerID'

The above exception was the direct cause of the following exception:

Traceback (most recent call last):
  File "box\\box.py", line 632, in box.box.Box.__getattr__
  File "box\\box.py", line 620, in box.box.Box.__getitem__
box.exceptions.BoxKeyError: "'CustomerID'"

During handling of the above exception, another exception occurred:

Traceback (most recent call last):
  File "box\\box.py", line 634, in box.box.Box.__getattr__
AttributeError: 'ConfigBox' object has no attribute 'CustomerID'

The above exception was the direct cause of the following exception:

Traceback (most recent call last):
  File "box\\config_box.py", line 29, in box.config_box.ConfigBox.__getattr__
  File "box\\box.py", line 648, in box.box.Box.__getattr__
box.exceptions.BoxKeyError: "'ConfigBox' object has no attribute 'CustomerID'"

During handling of the above exception, another exception occurred:

Traceback (most recent call last):
  File "box\\box.py", line 593, in box.box.Box.__getitem__
KeyError: 'customerid'

The above exception was the direct cause of the following exception:

Traceback (most recent call last):
  File "box\\box.py", line 632, in box.box.Box.__getattr__
  File "box\\box.py", line 620, in box.box.Box.__getitem__
box.exceptions.BoxKeyError: "'customerid'"

During handling of the above exception, another exception occurred:

Traceback (most recent call last):
  File "box\\box.py", line 634, in box.box.Box.__getattr__
AttributeError: 'ConfigBox' object has no attribute 'customerid'

The above exception was the direct cause of the following exception:

Traceback (most recent call last):
  File "D:\repositories\coustomer churn prediction\etl_main.py", line 19, in <module>
    data_transformation.initiate_data_Transformation()
  File "D:\repositories\coustomer churn prediction\src\churn_etl\pipeline\data_transformation_pipeline.py", line 17, in initiate_data_Transformation
    raise e
  File "D:\repositories\coustomer churn prediction\src\churn_etl\pipeline\data_transformation_pipeline.py", line 13, in initiate_data_Transformation
    data_Transformation_config = config.get_data_transformation_config()
  File "D:\repositories\coustomer churn prediction\src\churn_etl\config\configuration.py", line 43, in get_data_transformation_config
    "CustomerID": str(config.CustomerID),
  File "box\\config_box.py", line 31, in box.config_box.ConfigBox.__getattr__
  File "box\\box.py", line 648, in box.box.Box.__getattr__
box.exceptions.BoxKeyError: "'ConfigBox' object has no attribute 'customerid'"
[2024-12-11 19:18:35,381: INFO: etl_main: >>>>>>> stage Data Extraction Stage started <<<<<<<<]
[2024-12-11 19:18:35,383: INFO: common: yaml file: D:\repositories\coustomer churn prediction\config\etl_config.yaml loaded successfully]
[2024-12-11 19:18:35,383: INFO: common: Directory ETL_artifacts created successfully]
[2024-12-11 19:18:35,383: INFO: common: Directory artifacts/data_Extracting created successfully]
[2024-12-11 19:18:41,417: INFO: data_extracting: data succesfully fetched from customer_churn_data and table customers]
[2024-12-11 19:18:41,417: INFO: etl_main: >>>>>>> stage Data Extraction Stage completed <<<<<<<<

=================x]
[2024-12-11 19:18:41,417: INFO: etl_main: >>>>>>> stage Data Transformation Stage started <<<<<<<<]
[2024-12-11 19:18:41,429: INFO: common: yaml file: D:\repositories\coustomer churn prediction\config\etl_config.yaml loaded successfully]
[2024-12-11 19:18:41,430: INFO: common: Directory ETL_artifacts created successfully]
[2024-12-11 19:18:41,430: INFO: common: Directory artifacts/data_transformation created successfully]
[2024-12-11 19:18:41,430: ERROR: etl_main: "'ConfigBox' object has no attribute 'customerid'"]
Traceback (most recent call last):
  File "box\\box.py", line 593, in box.box.Box.__getitem__
KeyError: 'CustomerID'

The above exception was the direct cause of the following exception:

Traceback (most recent call last):
  File "box\\box.py", line 632, in box.box.Box.__getattr__
  File "box\\box.py", line 620, in box.box.Box.__getitem__
box.exceptions.BoxKeyError: "'CustomerID'"

During handling of the above exception, another exception occurred:

Traceback (most recent call last):
  File "box\\box.py", line 634, in box.box.Box.__getattr__
AttributeError: 'ConfigBox' object has no attribute 'CustomerID'

The above exception was the direct cause of the following exception:

Traceback (most recent call last):
  File "box\\config_box.py", line 29, in box.config_box.ConfigBox.__getattr__
  File "box\\box.py", line 648, in box.box.Box.__getattr__
box.exceptions.BoxKeyError: "'ConfigBox' object has no attribute 'CustomerID'"

During handling of the above exception, another exception occurred:

Traceback (most recent call last):
  File "box\\box.py", line 593, in box.box.Box.__getitem__
KeyError: 'customerid'

The above exception was the direct cause of the following exception:

Traceback (most recent call last):
  File "box\\box.py", line 632, in box.box.Box.__getattr__
  File "box\\box.py", line 620, in box.box.Box.__getitem__
box.exceptions.BoxKeyError: "'customerid'"

During handling of the above exception, another exception occurred:

Traceback (most recent call last):
  File "box\\box.py", line 634, in box.box.Box.__getattr__
AttributeError: 'ConfigBox' object has no attribute 'customerid'

The above exception was the direct cause of the following exception:

Traceback (most recent call last):
  File "D:\repositories\coustomer churn prediction\etl_main.py", line 19, in <module>
    data_transformation.initiate_data_Transformation()
  File "D:\repositories\coustomer churn prediction\src\churn_etl\pipeline\data_transformation_pipeline.py", line 17, in initiate_data_Transformation
    raise e
  File "D:\repositories\coustomer churn prediction\src\churn_etl\pipeline\data_transformation_pipeline.py", line 13, in initiate_data_Transformation
    data_Transformation_config = config.get_data_transformation_config()
  File "D:\repositories\coustomer churn prediction\src\churn_etl\config\configuration.py", line 43, in get_data_transformation_config
    "CustomerID": str(config.CustomerID),
  File "box\\config_box.py", line 31, in box.config_box.ConfigBox.__getattr__
  File "box\\box.py", line 648, in box.box.Box.__getattr__
box.exceptions.BoxKeyError: "'ConfigBox' object has no attribute 'customerid'"
[2024-12-11 19:19:11,561: INFO: etl_main: >>>>>>> stage Data Extraction Stage started <<<<<<<<]
[2024-12-11 19:19:11,564: INFO: common: yaml file: D:\repositories\coustomer churn prediction\config\etl_config.yaml loaded successfully]
[2024-12-11 19:19:11,564: INFO: common: Directory ETL_artifacts created successfully]
[2024-12-11 19:19:11,567: INFO: common: Directory artifacts/data_Extracting created successfully]
[2024-12-11 19:19:17,565: INFO: data_extracting: data succesfully fetched from customer_churn_data and table customers]
[2024-12-11 19:19:17,565: INFO: etl_main: >>>>>>> stage Data Extraction Stage completed <<<<<<<<

=================x]
[2024-12-11 19:19:17,565: INFO: etl_main: >>>>>>> stage Data Transformation Stage started <<<<<<<<]
[2024-12-11 19:19:17,565: INFO: common: yaml file: D:\repositories\coustomer churn prediction\config\etl_config.yaml loaded successfully]
[2024-12-11 19:19:17,565: INFO: common: Directory ETL_artifacts created successfully]
[2024-12-11 19:19:17,565: INFO: common: Directory artifacts/data_transformation created successfully]
[2024-12-11 19:19:17,565: ERROR: etl_main: "'ConfigBox' object has no attribute 'customerid'"]
Traceback (most recent call last):
  File "box\\box.py", line 593, in box.box.Box.__getitem__
KeyError: 'CustomerID'

The above exception was the direct cause of the following exception:

Traceback (most recent call last):
  File "box\\box.py", line 632, in box.box.Box.__getattr__
  File "box\\box.py", line 620, in box.box.Box.__getitem__
box.exceptions.BoxKeyError: "'CustomerID'"

During handling of the above exception, another exception occurred:

Traceback (most recent call last):
  File "box\\box.py", line 634, in box.box.Box.__getattr__
AttributeError: 'ConfigBox' object has no attribute 'CustomerID'

The above exception was the direct cause of the following exception:

Traceback (most recent call last):
  File "box\\config_box.py", line 29, in box.config_box.ConfigBox.__getattr__
  File "box\\box.py", line 648, in box.box.Box.__getattr__
box.exceptions.BoxKeyError: "'ConfigBox' object has no attribute 'CustomerID'"

During handling of the above exception, another exception occurred:

Traceback (most recent call last):
  File "box\\box.py", line 593, in box.box.Box.__getitem__
KeyError: 'customerid'

The above exception was the direct cause of the following exception:

Traceback (most recent call last):
  File "box\\box.py", line 632, in box.box.Box.__getattr__
  File "box\\box.py", line 620, in box.box.Box.__getitem__
box.exceptions.BoxKeyError: "'customerid'"

During handling of the above exception, another exception occurred:

Traceback (most recent call last):
  File "box\\box.py", line 634, in box.box.Box.__getattr__
AttributeError: 'ConfigBox' object has no attribute 'customerid'

The above exception was the direct cause of the following exception:

Traceback (most recent call last):
  File "D:\repositories\coustomer churn prediction\etl_main.py", line 19, in <module>
    data_transformation.initiate_data_Transformation()
  File "D:\repositories\coustomer churn prediction\src\churn_etl\pipeline\data_transformation_pipeline.py", line 17, in initiate_data_Transformation
    raise e
  File "D:\repositories\coustomer churn prediction\src\churn_etl\pipeline\data_transformation_pipeline.py", line 13, in initiate_data_Transformation
    data_Transformation_config = config.get_data_transformation_config()
  File "D:\repositories\coustomer churn prediction\src\churn_etl\config\configuration.py", line 43, in get_data_transformation_config
    "CustomerID": str(config.CustomerID),
  File "box\\config_box.py", line 31, in box.config_box.ConfigBox.__getattr__
  File "box\\box.py", line 648, in box.box.Box.__getattr__
box.exceptions.BoxKeyError: "'ConfigBox' object has no attribute 'customerid'"
[2024-12-11 19:35:05,448: INFO: etl_main: >>>>>>> stage Data Extraction Stage started <<<<<<<<]
[2024-12-11 19:35:05,451: INFO: common: yaml file: D:\repositories\coustomer churn prediction\config\etl_config.yaml loaded successfully]
[2024-12-11 19:35:05,451: INFO: common: Directory ETL_artifacts created successfully]
[2024-12-11 19:35:05,451: INFO: common: Directory artifacts/data_Extracting created successfully]
[2024-12-11 19:35:11,784: INFO: data_extracting: data succesfully fetched from customer_churn_data and table customers]
[2024-12-11 19:35:11,784: INFO: etl_main: >>>>>>> stage Data Extraction Stage completed <<<<<<<<

=================x]
[2024-12-11 19:35:11,784: INFO: etl_main: >>>>>>> stage Data Transformation Stage started <<<<<<<<]
[2024-12-11 19:35:11,784: INFO: common: yaml file: D:\repositories\coustomer churn prediction\config\etl_config.yaml loaded successfully]
[2024-12-11 19:35:11,784: INFO: common: Directory ETL_artifacts created successfully]
[2024-12-11 19:35:11,784: INFO: common: Directory artifacts/data_transformation created successfully]
[2024-12-11 19:35:11,784: ERROR: etl_main: 'DataExtractingArtifact' object has no attribute 'data']
Traceback (most recent call last):
  File "D:\repositories\coustomer churn prediction\etl_main.py", line 19, in <module>
    data_transformation.initiate_data_Transformation()
  File "D:\repositories\coustomer churn prediction\src\churn_etl\pipeline\data_transformation_pipeline.py", line 17, in initiate_data_Transformation
    raise e
  File "D:\repositories\coustomer churn prediction\src\churn_etl\pipeline\data_transformation_pipeline.py", line 15, in initiate_data_Transformation
    data_Transformation.transform_data()
  File "D:\repositories\coustomer churn prediction\src\churn_etl\components\data_transformation.py", line 32, in transform_data
    validation_status = self.validate_schema(self.artifact.data)
AttributeError: 'DataExtractingArtifact' object has no attribute 'data'
[2024-12-11 19:40:21,218: INFO: etl_main: >>>>>>> stage Data Extraction Stage started <<<<<<<<]
[2024-12-11 19:40:21,218: INFO: common: yaml file: D:\repositories\coustomer churn prediction\config\etl_config.yaml loaded successfully]
[2024-12-11 19:40:21,218: INFO: common: Directory ETL_artifacts created successfully]
[2024-12-11 19:40:21,218: INFO: common: Directory artifacts/data_Extracting created successfully]
[2024-12-11 19:40:27,136: INFO: data_extracting: data succesfully fetched from customer_churn_data and table customers]
[2024-12-11 19:40:27,150: INFO: etl_main: >>>>>>> stage Data Extraction Stage completed <<<<<<<<

=================x]
[2024-12-11 19:40:27,150: INFO: etl_main: >>>>>>> stage Data Transformation Stage started <<<<<<<<]
[2024-12-11 19:40:27,150: INFO: common: yaml file: D:\repositories\coustomer churn prediction\config\etl_config.yaml loaded successfully]
[2024-12-11 19:40:27,150: INFO: common: Directory ETL_artifacts created successfully]
[2024-12-11 19:40:27,150: INFO: common: Directory artifacts/data_transformation created successfully]
[2024-12-11 19:40:27,150: ERROR: etl_main: 'DataTrasformer' object has no attribute 'expected_columns']
Traceback (most recent call last):
  File "D:\repositories\coustomer churn prediction\etl_main.py", line 19, in <module>
    data_transformation.initiate_data_Transformation()
  File "D:\repositories\coustomer churn prediction\src\churn_etl\pipeline\data_transformation_pipeline.py", line 17, in initiate_data_Transformation
    raise e
  File "D:\repositories\coustomer churn prediction\src\churn_etl\pipeline\data_transformation_pipeline.py", line 15, in initiate_data_Transformation
    data_Transformation.transform_data()
  File "D:\repositories\coustomer churn prediction\src\churn_etl\components\data_transformation.py", line 32, in transform_data
    validation_status = self.validate_schema(self.artifact.loaded_data_frame)
  File "D:\repositories\coustomer churn prediction\src\churn_etl\components\data_transformation.py", line 23, in validate_schema
    for col, expected_dtype in self.expected_columns.items():
AttributeError: 'DataTrasformer' object has no attribute 'expected_columns'
[2024-12-11 19:50:15,036: INFO: etl_main: >>>>>>> stage Data Extraction Stage started <<<<<<<<]
[2024-12-11 19:50:15,036: INFO: common: yaml file: D:\repositories\coustomer churn prediction\config\etl_config.yaml loaded successfully]
[2024-12-11 19:50:15,036: INFO: common: Directory ETL_artifacts created successfully]
[2024-12-11 19:50:15,036: INFO: common: Directory artifacts/data_Extracting created successfully]
[2024-12-11 19:50:21,611: INFO: data_extracting: data succesfully fetched from customer_churn_data and table customers]
[2024-12-11 19:50:21,611: INFO: etl_main: >>>>>>> stage Data Extraction Stage completed <<<<<<<<

=================x]
[2024-12-11 19:50:21,611: INFO: etl_main: >>>>>>> stage Data Transformation Stage started <<<<<<<<]
[2024-12-11 19:50:21,611: INFO: common: yaml file: D:\repositories\coustomer churn prediction\config\etl_config.yaml loaded successfully]
[2024-12-11 19:50:21,611: INFO: common: Directory ETL_artifacts created successfully]
[2024-12-11 19:50:21,611: INFO: common: Directory artifacts/data_transformation created successfully]
[2024-12-11 19:50:21,611: INFO: data_transformation: Schema Validation Passed: Column names and data types match expectations.]
[2024-12-11 19:50:21,623: INFO: etl_main: >>>>>>> stage Data Transformation Stage completed <<<<<<<<

=================x]
[2024-12-11 20:23:09,075: INFO: etl_main: >>>>>>> stage Data Extraction Stage started <<<<<<<<]
[2024-12-11 20:23:09,076: INFO: common: yaml file: D:\repositories\coustomer churn prediction\config\etl_config.yaml loaded successfully]
[2024-12-11 20:23:09,076: INFO: common: Directory ETL_artifacts created successfully]
[2024-12-11 20:23:09,076: INFO: common: Directory artifacts/data_Extracting created successfully]
[2024-12-11 20:23:14,747: INFO: data_extracting: data succesfully fetched from customer_churn_data and table customers]
[2024-12-11 20:23:14,747: INFO: etl_main: >>>>>>> stage Data Extraction Stage completed <<<<<<<<

=================x]
[2024-12-11 20:23:14,747: INFO: etl_main: >>>>>>> stage Data Transformation Stage started <<<<<<<<]
[2024-12-11 20:23:14,755: INFO: common: yaml file: D:\repositories\coustomer churn prediction\config\etl_config.yaml loaded successfully]
[2024-12-11 20:23:14,755: INFO: common: Directory ETL_artifacts created successfully]
[2024-12-11 20:23:14,755: INFO: common: Directory artifacts/data_transformation created successfully]
[2024-12-11 20:23:14,755: INFO: data_transformation: Schema Validation Passed: Column names and data types match expectations.]
[2024-12-11 20:23:14,755: ERROR: etl_main: 'NoneType' object has no attribute 'transformed_data_frame']
Traceback (most recent call last):
  File "D:\repositories\coustomer churn prediction\etl_main.py", line 20, in <module>
    print(data_trasformation_artifact.transformed_data_frame.isnull().sum())
AttributeError: 'NoneType' object has no attribute 'transformed_data_frame'
[2024-12-11 20:25:02,933: INFO: etl_main: >>>>>>> stage Data Extraction Stage started <<<<<<<<]
[2024-12-11 20:25:02,936: INFO: common: yaml file: D:\repositories\coustomer churn prediction\config\etl_config.yaml loaded successfully]
[2024-12-11 20:25:02,937: INFO: common: Directory ETL_artifacts created successfully]
[2024-12-11 20:25:02,937: INFO: common: Directory artifacts/data_Extracting created successfully]
[2024-12-11 20:25:08,590: INFO: data_extracting: data succesfully fetched from customer_churn_data and table customers]
[2024-12-11 20:25:08,590: INFO: etl_main: >>>>>>> stage Data Extraction Stage completed <<<<<<<<

=================x]
[2024-12-11 20:25:08,590: INFO: etl_main: >>>>>>> stage Data Transformation Stage started <<<<<<<<]
[2024-12-11 20:25:08,590: INFO: common: yaml file: D:\repositories\coustomer churn prediction\config\etl_config.yaml loaded successfully]
[2024-12-11 20:25:08,590: INFO: common: Directory ETL_artifacts created successfully]
[2024-12-11 20:25:08,590: INFO: common: Directory artifacts/data_transformation created successfully]
[2024-12-11 20:25:08,590: INFO: data_transformation: Schema Validation Passed: Column names and data types match expectations.]
[2024-12-11 20:25:08,590: ERROR: etl_main: 'NoneType' object has no attribute 'transformed_data_frame']
Traceback (most recent call last):
  File "D:\repositories\coustomer churn prediction\etl_main.py", line 20, in <module>
    print(data_trasformation_artifact.transformed_data_frame.isnull().sum())
AttributeError: 'NoneType' object has no attribute 'transformed_data_frame'
[2024-12-11 20:27:14,170: INFO: etl_main: >>>>>>> stage Data Extraction Stage started <<<<<<<<]
[2024-12-11 20:27:14,170: INFO: common: yaml file: D:\repositories\coustomer churn prediction\config\etl_config.yaml loaded successfully]
[2024-12-11 20:27:14,170: INFO: common: Directory ETL_artifacts created successfully]
[2024-12-11 20:27:14,170: INFO: common: Directory artifacts/data_Extracting created successfully]
[2024-12-11 20:27:19,927: INFO: data_extracting: data succesfully fetched from customer_churn_data and table customers]
[2024-12-11 20:27:19,927: INFO: etl_main: >>>>>>> stage Data Extraction Stage completed <<<<<<<<

=================x]
[2024-12-11 20:27:19,927: INFO: etl_main: >>>>>>> stage Data Transformation Stage started <<<<<<<<]
[2024-12-11 20:27:19,930: INFO: common: yaml file: D:\repositories\coustomer churn prediction\config\etl_config.yaml loaded successfully]
[2024-12-11 20:27:19,930: INFO: common: Directory ETL_artifacts created successfully]
[2024-12-11 20:27:19,930: INFO: common: Directory artifacts/data_transformation created successfully]
[2024-12-11 20:27:19,930: INFO: data_transformation: Schema Validation Passed: Column names and data types match expectations.]
[2024-12-11 20:27:19,930: ERROR: etl_main: 'NoneType' object has no attribute 'transformed_data_frame']
Traceback (most recent call last):
  File "D:\repositories\coustomer churn prediction\etl_main.py", line 20, in <module>
    print(data_trasformation_artifact.transformed_data_frame.isnull().sum())
AttributeError: 'NoneType' object has no attribute 'transformed_data_frame'
[2024-12-11 20:28:24,130: INFO: etl_main: >>>>>>> stage Data Extraction Stage started <<<<<<<<]
[2024-12-11 20:28:24,146: INFO: common: yaml file: D:\repositories\coustomer churn prediction\config\etl_config.yaml loaded successfully]
[2024-12-11 20:28:24,146: INFO: common: Directory ETL_artifacts created successfully]
[2024-12-11 20:28:24,146: INFO: common: Directory artifacts/data_Extracting created successfully]
[2024-12-11 20:28:30,352: INFO: data_extracting: data succesfully fetched from customer_churn_data and table customers]
[2024-12-11 20:28:30,352: INFO: etl_main: >>>>>>> stage Data Extraction Stage completed <<<<<<<<

=================x]
[2024-12-11 20:28:30,352: INFO: etl_main: >>>>>>> stage Data Transformation Stage started <<<<<<<<]
[2024-12-11 20:28:30,352: INFO: common: yaml file: D:\repositories\coustomer churn prediction\config\etl_config.yaml loaded successfully]
[2024-12-11 20:28:30,352: INFO: common: Directory ETL_artifacts created successfully]
[2024-12-11 20:28:30,352: INFO: common: Directory artifacts/data_transformation created successfully]
[2024-12-11 20:28:30,352: INFO: data_transformation: Schema Validation Passed: Column names and data types match expectations.]
[2024-12-11 20:28:30,352: INFO: etl_main: >>>>>>> stage Data Transformation Stage completed <<<<<<<<

=================x]
[2024-12-11 20:29:20,608: INFO: etl_main: >>>>>>> stage Data Extraction Stage started <<<<<<<<]
[2024-12-11 20:29:20,608: INFO: common: yaml file: D:\repositories\coustomer churn prediction\config\etl_config.yaml loaded successfully]
[2024-12-11 20:29:20,608: INFO: common: Directory ETL_artifacts created successfully]
[2024-12-11 20:29:20,608: INFO: common: Directory artifacts/data_Extracting created successfully]
[2024-12-11 20:29:26,361: INFO: data_extracting: data succesfully fetched from customer_churn_data and table customers]
[2024-12-11 20:29:26,361: INFO: etl_main: >>>>>>> stage Data Extraction Stage completed <<<<<<<<

=================x]
[2024-12-11 20:29:26,361: INFO: etl_main: >>>>>>> stage Data Transformation Stage started <<<<<<<<]
[2024-12-11 20:29:26,361: INFO: common: yaml file: D:\repositories\coustomer churn prediction\config\etl_config.yaml loaded successfully]
[2024-12-11 20:29:26,361: INFO: common: Directory ETL_artifacts created successfully]
[2024-12-11 20:29:26,361: INFO: common: Directory artifacts/data_transformation created successfully]
[2024-12-11 20:29:26,361: INFO: data_transformation: Schema Validation Passed: Column names and data types match expectations.]
[2024-12-11 20:29:26,361: INFO: etl_main: >>>>>>> stage Data Transformation Stage completed <<<<<<<<

=================x]
[2024-12-11 20:29:52,981: INFO: etl_main: >>>>>>> stage Data Extraction Stage started <<<<<<<<]
[2024-12-11 20:29:52,984: INFO: common: yaml file: D:\repositories\coustomer churn prediction\config\etl_config.yaml loaded successfully]
[2024-12-11 20:29:52,985: INFO: common: Directory ETL_artifacts created successfully]
[2024-12-11 20:29:52,985: INFO: common: Directory artifacts/data_Extracting created successfully]
[2024-12-11 20:29:58,870: INFO: data_extracting: data succesfully fetched from customer_churn_data and table customers]
[2024-12-11 20:29:58,870: INFO: etl_main: >>>>>>> stage Data Extraction Stage completed <<<<<<<<

=================x]
[2024-12-11 20:29:58,870: INFO: etl_main: >>>>>>> stage Data Transformation Stage started <<<<<<<<]
[2024-12-11 20:29:58,870: INFO: common: yaml file: D:\repositories\coustomer churn prediction\config\etl_config.yaml loaded successfully]
[2024-12-11 20:29:58,870: INFO: common: Directory ETL_artifacts created successfully]
[2024-12-11 20:29:58,870: INFO: common: Directory artifacts/data_transformation created successfully]
[2024-12-11 20:29:58,870: INFO: data_transformation: Schema Validation Passed: Column names and data types match expectations.]
[2024-12-11 20:29:58,870: INFO: etl_main: >>>>>>> stage Data Transformation Stage completed <<<<<<<<

=================x]
[2024-12-11 20:31:17,188: INFO: etl_main: >>>>>>> stage Data Extraction Stage started <<<<<<<<]
[2024-12-11 20:31:17,192: INFO: common: yaml file: D:\repositories\coustomer churn prediction\config\etl_config.yaml loaded successfully]
[2024-12-11 20:31:17,192: INFO: common: Directory ETL_artifacts created successfully]
[2024-12-11 20:31:17,193: INFO: common: Directory artifacts/data_Extracting created successfully]
[2024-12-11 20:31:23,023: INFO: data_extracting: data succesfully fetched from customer_churn_data and table customers]
[2024-12-11 20:31:23,023: INFO: etl_main: >>>>>>> stage Data Extraction Stage completed <<<<<<<<

=================x]
[2024-12-11 20:31:23,023: INFO: etl_main: >>>>>>> stage Data Transformation Stage started <<<<<<<<]
[2024-12-11 20:31:23,039: INFO: common: yaml file: D:\repositories\coustomer churn prediction\config\etl_config.yaml loaded successfully]
[2024-12-11 20:31:23,039: INFO: common: Directory ETL_artifacts created successfully]
[2024-12-11 20:31:23,039: INFO: common: Directory artifacts/data_transformation created successfully]
[2024-12-11 20:31:23,039: INFO: data_transformation: Schema Validation Passed: Column names and data types match expectations.]
[2024-12-11 20:31:23,039: ERROR: etl_main: local variable 'transformed_data' referenced before assignment]
Traceback (most recent call last):
  File "D:\repositories\coustomer churn prediction\etl_main.py", line 19, in <module>
    data_trasformation_artifact = data_transformation.initiate_data_Transformation()
  File "D:\repositories\coustomer churn prediction\src\churn_etl\pipeline\data_transformation_pipeline.py", line 18, in initiate_data_Transformation
    raise e
  File "D:\repositories\coustomer churn prediction\src\churn_etl\pipeline\data_transformation_pipeline.py", line 15, in initiate_data_Transformation
    data_trasformation_artifact = data_Transformation.transform_data()
  File "D:\repositories\coustomer churn prediction\src\churn_etl\components\data_transformation.py", line 81, in transform_data
    transformed_data = self.handle_duplicates(transformed_data)
UnboundLocalError: local variable 'transformed_data' referenced before assignment
[2024-12-11 20:32:00,160: INFO: etl_main: >>>>>>> stage Data Extraction Stage started <<<<<<<<]
[2024-12-11 20:32:00,160: INFO: common: yaml file: D:\repositories\coustomer churn prediction\config\etl_config.yaml loaded successfully]
[2024-12-11 20:32:00,160: INFO: common: Directory ETL_artifacts created successfully]
[2024-12-11 20:32:00,160: INFO: common: Directory artifacts/data_Extracting created successfully]
[2024-12-11 20:32:05,974: INFO: data_extracting: data succesfully fetched from customer_churn_data and table customers]
[2024-12-11 20:32:05,974: INFO: etl_main: >>>>>>> stage Data Extraction Stage completed <<<<<<<<

=================x]
[2024-12-11 20:32:05,974: INFO: etl_main: >>>>>>> stage Data Transformation Stage started <<<<<<<<]
[2024-12-11 20:32:05,982: INFO: common: yaml file: D:\repositories\coustomer churn prediction\config\etl_config.yaml loaded successfully]
[2024-12-11 20:32:05,982: INFO: common: Directory ETL_artifacts created successfully]
[2024-12-11 20:32:05,982: INFO: common: Directory artifacts/data_transformation created successfully]
[2024-12-11 20:32:05,982: INFO: data_transformation: Schema Validation Passed: Column names and data types match expectations.]
[2024-12-11 20:32:05,997: INFO: data_transformation: No duplicate rows found.]
[2024-12-11 20:32:05,997: ERROR: etl_main: DataTrasformer.handle_missing_values() takes 1 positional argument but 2 were given]
Traceback (most recent call last):
  File "D:\repositories\coustomer churn prediction\etl_main.py", line 19, in <module>
    data_trasformation_artifact = data_transformation.initiate_data_Transformation()
  File "D:\repositories\coustomer churn prediction\src\churn_etl\pipeline\data_transformation_pipeline.py", line 18, in initiate_data_Transformation
    raise e
  File "D:\repositories\coustomer churn prediction\src\churn_etl\pipeline\data_transformation_pipeline.py", line 15, in initiate_data_Transformation
    data_trasformation_artifact = data_Transformation.transform_data()
  File "D:\repositories\coustomer churn prediction\src\churn_etl\components\data_transformation.py", line 82, in transform_data
    transformed_data = self.handle_missing_values(transformed_data)
TypeError: DataTrasformer.handle_missing_values() takes 1 positional argument but 2 were given
[2024-12-11 20:33:46,713: INFO: etl_main: >>>>>>> stage Data Extraction Stage started <<<<<<<<]
[2024-12-11 20:33:46,719: INFO: common: yaml file: D:\repositories\coustomer churn prediction\config\etl_config.yaml loaded successfully]
[2024-12-11 20:33:46,719: INFO: common: Directory ETL_artifacts created successfully]
[2024-12-11 20:33:46,719: INFO: common: Directory artifacts/data_Extracting created successfully]
[2024-12-11 20:33:53,601: INFO: data_extracting: data succesfully fetched from customer_churn_data and table customers]
[2024-12-11 20:33:53,601: INFO: etl_main: >>>>>>> stage Data Extraction Stage completed <<<<<<<<

=================x]
[2024-12-11 20:33:53,601: INFO: etl_main: >>>>>>> stage Data Transformation Stage started <<<<<<<<]
[2024-12-11 20:33:53,607: INFO: common: yaml file: D:\repositories\coustomer churn prediction\config\etl_config.yaml loaded successfully]
[2024-12-11 20:33:53,607: INFO: common: Directory ETL_artifacts created successfully]
[2024-12-11 20:33:53,607: INFO: common: Directory artifacts/data_transformation created successfully]
[2024-12-11 20:33:53,610: INFO: data_transformation: Schema Validation Passed: Column names and data types match expectations.]
[2024-12-11 20:33:53,613: INFO: data_transformation: No duplicate rows found.]
[2024-12-11 20:34:19,127: INFO: data_transformation: misssing values handled succesfully.]
[2024-12-11 20:34:19,163: INFO: etl_main: >>>>>>> stage Data Transformation Stage completed <<<<<<<<

=================x]
[2024-12-11 20:37:39,077: INFO: etl_main: >>>>>>> stage Data Extraction Stage started <<<<<<<<]
[2024-12-11 20:37:39,077: INFO: common: yaml file: D:\repositories\coustomer churn prediction\config\etl_config.yaml loaded successfully]
[2024-12-11 20:37:39,077: INFO: common: Directory ETL_artifacts created successfully]
[2024-12-11 20:37:39,077: INFO: common: Directory artifacts/data_Extracting created successfully]
[2024-12-11 20:37:45,156: INFO: data_extracting: data succesfully fetched from customer_churn_data and table customers]
[2024-12-11 20:37:45,156: INFO: etl_main: >>>>>>> stage Data Extraction Stage completed <<<<<<<<

=================x]
[2024-12-11 20:37:45,156: INFO: etl_main: >>>>>>> stage Data Transformation Stage started <<<<<<<<]
[2024-12-11 20:37:45,158: INFO: common: yaml file: D:\repositories\coustomer churn prediction\config\etl_config.yaml loaded successfully]
[2024-12-11 20:37:45,158: INFO: common: Directory ETL_artifacts created successfully]
[2024-12-11 20:37:45,158: INFO: common: Directory artifacts/data_transformation created successfully]
[2024-12-11 20:37:45,158: INFO: data_transformation: Schema Validation Passed: Column names and data types match expectations.]
[2024-12-11 20:37:45,163: INFO: data_transformation: No duplicate rows found.]
[2024-12-11 20:38:09,834: INFO: data_transformation: misssing values handled succesfully.]
[2024-12-11 20:38:09,868: INFO: etl_main: >>>>>>> stage Data Transformation Stage completed <<<<<<<<

=================x]
[2024-12-12 11:16:20,109: INFO: etl_main: >>>>>>> stage Data Extraction Stage started <<<<<<<<]
[2024-12-12 11:16:20,109: ERROR: etl_main: [Errno 2] No such file or directory: 'D:\\repositories\\coustomer churn prediction\\config\\etl_config.yaml']
Traceback (most recent call last):
  File "D:\repositories\coustomer_churn_prediction_system\etl_main.py", line 10, in <module>
    dataextractionartifact = data_extraction.initiate_data_extraction()
  File "D:\repositories\coustomer_churn_prediction_system\src\churn_etl\pipeline\data_extraction_pipeline.py", line 17, in initiate_data_extraction
    raise e
  File "D:\repositories\coustomer_churn_prediction_system\src\churn_etl\pipeline\data_extraction_pipeline.py", line 11, in initiate_data_extraction
    config = ETLConfigurationManager()
  File "D:\repositories\coustomer_churn_prediction_system\src\churn_etl\config\configuration.py", line 10, in __init__
    self.config = read_yaml(config_filepath)
  File "d:\repositories\coustomer_churn_prediction_system\venv\lib\site-packages\ensure\main.py", line 872, in __call__
    return_val = self.f(*args, **kwargs)
  File "D:\repositories\coustomer_churn_prediction_system\src\churn_etl\utils\common.py", line 28, in read_yaml
    raise e
  File "D:\repositories\coustomer_churn_prediction_system\src\churn_etl\utils\common.py", line 21, in read_yaml
    with open(path_to_yaml) as yamlfile:
FileNotFoundError: [Errno 2] No such file or directory: 'D:\\repositories\\coustomer churn prediction\\config\\etl_config.yaml'
[2024-12-12 11:17:11,063: INFO: etl_main: >>>>>>> stage Data Extraction Stage started <<<<<<<<]
[2024-12-12 11:17:11,063: INFO: common: yaml file: D:\repositories\coustomer_churn_prediction_system\config\etl_config.yaml loaded successfully]
[2024-12-12 11:17:11,063: INFO: common: Directory ETL_artifacts created successfully]
[2024-12-12 11:17:11,063: INFO: common: Directory artifacts/data_Extracting created successfully]
[2024-12-12 11:17:18,313: INFO: data_extracting: data succesfully fetched from customer_churn_data and table customers]
[2024-12-12 11:17:18,313: INFO: etl_main: >>>>>>> stage Data Extraction Stage completed <<<<<<<<

=================x]
[2024-12-12 11:17:18,313: INFO: etl_main: >>>>>>> stage Data Transformation Stage started <<<<<<<<]
[2024-12-12 11:17:18,328: INFO: common: yaml file: D:\repositories\coustomer_churn_prediction_system\config\etl_config.yaml loaded successfully]
[2024-12-12 11:17:18,328: INFO: common: Directory ETL_artifacts created successfully]
[2024-12-12 11:17:18,328: INFO: common: Directory artifacts/data_transformation created successfully]
[2024-12-12 11:17:18,328: INFO: data_transformation: Schema Validation Passed: Column names and data types match expectations.]
[2024-12-12 11:17:18,330: INFO: data_transformation: No duplicate rows found.]
[2024-12-12 11:17:43,320: INFO: data_transformation: misssing values handled succesfully.]
[2024-12-12 11:17:43,348: INFO: etl_main: >>>>>>> stage Data Transformation Stage completed <<<<<<<<

=================x]
[2024-12-12 11:17:43,348: INFO: etl_main: >>>>>>> stage Data Loading Stage started <<<<<<<<]
[2024-12-12 11:17:43,350: INFO: common: yaml file: D:\repositories\coustomer_churn_prediction_system\config\etl_config.yaml loaded successfully]
[2024-12-12 11:17:43,350: INFO: common: Directory ETL_artifacts created successfully]
[2024-12-12 11:17:43,350: ERROR: etl_main: "'ConfigBox' object has no attribute 'root_dir'"]
Traceback (most recent call last):
  File "box\\box.py", line 593, in box.box.Box.__getitem__
KeyError: 'root_dir'

The above exception was the direct cause of the following exception:

Traceback (most recent call last):
  File "box\\box.py", line 632, in box.box.Box.__getattr__
  File "box\\box.py", line 620, in box.box.Box.__getitem__
box.exceptions.BoxKeyError: "'root_dir'"

During handling of the above exception, another exception occurred:

Traceback (most recent call last):
  File "box\\box.py", line 634, in box.box.Box.__getattr__
AttributeError: 'ConfigBox' object has no attribute 'root_dir'

The above exception was the direct cause of the following exception:

Traceback (most recent call last):
  File "box\\config_box.py", line 29, in box.config_box.ConfigBox.__getattr__
  File "box\\box.py", line 648, in box.box.Box.__getattr__
box.exceptions.BoxKeyError: "'ConfigBox' object has no attribute 'root_dir'"

During handling of the above exception, another exception occurred:

Traceback (most recent call last):
  File "box\\box.py", line 593, in box.box.Box.__getitem__
KeyError: 'root_dir'

The above exception was the direct cause of the following exception:

Traceback (most recent call last):
  File "box\\box.py", line 632, in box.box.Box.__getattr__
  File "box\\box.py", line 620, in box.box.Box.__getitem__
box.exceptions.BoxKeyError: "'root_dir'"

During handling of the above exception, another exception occurred:

Traceback (most recent call last):
  File "box\\box.py", line 634, in box.box.Box.__getattr__
AttributeError: 'ConfigBox' object has no attribute 'root_dir'

The above exception was the direct cause of the following exception:

Traceback (most recent call last):
  File "D:\repositories\coustomer_churn_prediction_system\etl_main.py", line 30, in <module>
    data_loading.initiate_data_Loading()
  File "D:\repositories\coustomer_churn_prediction_system\src\churn_etl\pipeline\data_loading_pipeline.py", line 17, in initiate_data_Loading
    raise e
  File "D:\repositories\coustomer_churn_prediction_system\src\churn_etl\pipeline\data_loading_pipeline.py", line 13, in initiate_data_Loading
    data_loading_config = config.get_data_laoding_config()
  File "D:\repositories\coustomer_churn_prediction_system\src\churn_etl\config\configuration.py", line 72, in get_data_laoding_config
    create_directories([self.config.root_dir])
  File "box\\config_box.py", line 31, in box.config_box.ConfigBox.__getattr__
  File "box\\box.py", line 648, in box.box.Box.__getattr__
box.exceptions.BoxKeyError: "'ConfigBox' object has no attribute 'root_dir'"
[2024-12-12 11:20:02,738: INFO: etl_main: >>>>>>> stage Data Extraction Stage started <<<<<<<<]
[2024-12-12 11:20:02,738: INFO: common: yaml file: D:\repositories\coustomer_churn_prediction_system\config\etl_config.yaml loaded successfully]
[2024-12-12 11:20:08,612: INFO: data_extracting: data succesfully fetched from customer_churn_data and table customers]
[2024-12-12 11:20:08,612: INFO: etl_main: >>>>>>> stage Data Extraction Stage completed <<<<<<<<

=================x]
[2024-12-12 11:20:08,612: INFO: etl_main: >>>>>>> stage Data Transformation Stage started <<<<<<<<]
[2024-12-12 11:20:08,616: INFO: common: yaml file: D:\repositories\coustomer_churn_prediction_system\config\etl_config.yaml loaded successfully]
[2024-12-12 11:20:08,616: INFO: data_transformation: Schema Validation Passed: Column names and data types match expectations.]
[2024-12-12 11:20:08,619: INFO: data_transformation: No duplicate rows found.]
[2024-12-12 11:20:33,893: INFO: data_transformation: misssing values handled succesfully.]
[2024-12-12 11:20:33,927: INFO: etl_main: >>>>>>> stage Data Transformation Stage completed <<<<<<<<

=================x]
[2024-12-12 11:20:33,930: INFO: etl_main: >>>>>>> stage Data Loading Stage started <<<<<<<<]
[2024-12-12 11:20:33,930: INFO: common: yaml file: D:\repositories\coustomer_churn_prediction_system\config\etl_config.yaml loaded successfully]
[2024-12-12 11:20:33,944: ERROR: data_loader: Error while loading data: Cannot save file into a non-existent directory: 'D:\repositories\coustomer churn prediction\src\churn_etl']
[2024-12-12 11:20:33,945: INFO: etl_main: >>>>>>> stage Data Loading Stage completed <<<<<<<<

=================x]
[2024-12-12 11:21:33,583: INFO: etl_main: >>>>>>> stage Data Extraction Stage started <<<<<<<<]
[2024-12-12 11:21:33,589: INFO: common: yaml file: D:\repositories\coustomer_churn_prediction_system\config\etl_config.yaml loaded successfully]
[2024-12-12 11:21:39,266: INFO: data_extracting: data succesfully fetched from customer_churn_data and table customers]
[2024-12-12 11:21:39,266: INFO: etl_main: >>>>>>> stage Data Extraction Stage completed <<<<<<<<

=================x]
[2024-12-12 11:21:39,266: INFO: etl_main: >>>>>>> stage Data Transformation Stage started <<<<<<<<]
[2024-12-12 11:21:39,279: INFO: common: yaml file: D:\repositories\coustomer_churn_prediction_system\config\etl_config.yaml loaded successfully]
[2024-12-12 11:21:39,282: INFO: data_transformation: Schema Validation Passed: Column names and data types match expectations.]
[2024-12-12 11:21:39,282: INFO: data_transformation: No duplicate rows found.]
[2024-12-12 11:22:04,246: INFO: data_transformation: misssing values handled succesfully.]
[2024-12-12 11:22:04,275: INFO: etl_main: >>>>>>> stage Data Transformation Stage completed <<<<<<<<

=================x]
[2024-12-12 11:22:04,275: INFO: etl_main: >>>>>>> stage Data Loading Stage started <<<<<<<<]
[2024-12-12 11:22:04,278: INFO: common: yaml file: D:\repositories\coustomer_churn_prediction_system\config\etl_config.yaml loaded successfully]
[2024-12-12 11:22:04,278: ERROR: data_loader: Error while loading data: [Errno 13] Permission denied: 'D:\\repositories\\coustomer_churn_prediction_system\\src\\churn_etl\\data']
[2024-12-12 11:22:04,278: INFO: etl_main: >>>>>>> stage Data Loading Stage completed <<<<<<<<

=================x]
[2024-12-12 11:23:09,234: INFO: etl_main: >>>>>>> stage Data Extraction Stage started <<<<<<<<]
[2024-12-12 11:23:09,238: INFO: common: yaml file: D:\repositories\coustomer_churn_prediction_system\config\etl_config.yaml loaded successfully]
[2024-12-12 11:23:15,819: INFO: data_extracting: data succesfully fetched from customer_churn_data and table customers]
[2024-12-12 11:23:15,819: INFO: etl_main: >>>>>>> stage Data Extraction Stage completed <<<<<<<<

=================x]
[2024-12-12 11:23:15,819: INFO: etl_main: >>>>>>> stage Data Transformation Stage started <<<<<<<<]
[2024-12-12 11:23:15,819: INFO: common: yaml file: D:\repositories\coustomer_churn_prediction_system\config\etl_config.yaml loaded successfully]
[2024-12-12 11:23:15,819: INFO: data_transformation: Schema Validation Passed: Column names and data types match expectations.]
[2024-12-12 11:23:15,819: INFO: data_transformation: No duplicate rows found.]
[2024-12-12 11:23:40,898: INFO: data_transformation: misssing values handled succesfully.]
[2024-12-12 11:23:40,919: INFO: etl_main: >>>>>>> stage Data Transformation Stage completed <<<<<<<<

=================x]
[2024-12-12 11:23:40,921: INFO: etl_main: >>>>>>> stage Data Loading Stage started <<<<<<<<]
[2024-12-12 11:23:40,923: INFO: common: yaml file: D:\repositories\coustomer_churn_prediction_system\config\etl_config.yaml loaded successfully]
[2024-12-12 11:23:40,925: ERROR: data_loader: Error while loading data: [Errno 13] Permission denied: 'D:\\repositories\\coustomer_churn_prediction_system\\data']
[2024-12-12 11:23:40,925: INFO: etl_main: >>>>>>> stage Data Loading Stage completed <<<<<<<<

=================x]
[2024-12-12 11:32:05,689: INFO: etl_main: >>>>>>> stage Data Extraction Stage started <<<<<<<<]
[2024-12-12 11:32:05,690: INFO: common: yaml file: D:\repositories\coustomer_churn_prediction_system\config\etl_config.yaml loaded successfully]
[2024-12-12 11:32:11,808: INFO: data_extracting: data succesfully fetched from customer_churn_data and table customers]
[2024-12-12 11:32:11,808: INFO: etl_main: >>>>>>> stage Data Extraction Stage completed <<<<<<<<

=================x]
[2024-12-12 11:32:11,808: INFO: etl_main: >>>>>>> stage Data Transformation Stage started <<<<<<<<]
[2024-12-12 11:32:11,825: INFO: common: yaml file: D:\repositories\coustomer_churn_prediction_system\config\etl_config.yaml loaded successfully]
[2024-12-12 11:32:11,825: INFO: data_transformation: Schema Validation Passed: Column names and data types match expectations.]
[2024-12-12 11:32:11,827: INFO: data_transformation: No duplicate rows found.]
[2024-12-12 11:32:36,866: INFO: data_transformation: misssing values handled succesfully.]
[2024-12-12 11:32:36,890: INFO: etl_main: >>>>>>> stage Data Transformation Stage completed <<<<<<<<

=================x]
[2024-12-12 11:32:36,890: INFO: etl_main: >>>>>>> stage Data Loading Stage started <<<<<<<<]
[2024-12-12 11:32:36,894: INFO: common: yaml file: D:\repositories\coustomer_churn_prediction_system\config\etl_config.yaml loaded successfully]
[2024-12-12 11:32:36,896: ERROR: data_loader: Error while loading data: [Errno 13] Permission denied: 'D:\\repositories\\story generation data\\kids_storeis_data']
[2024-12-12 11:32:36,896: INFO: etl_main: >>>>>>> stage Data Loading Stage completed <<<<<<<<

=================x]
[2024-12-12 15:10:37,881: INFO: etl_main: >>>>>>> stage Data Extraction Stage started <<<<<<<<]
[2024-12-12 15:10:37,884: INFO: common: yaml file: D:\repositories\coustomer_churn_prediction_system\config\etl_config.yaml loaded successfully]
[2024-12-12 15:10:51,510: INFO: data_extracting: data succesfully fetched from customer_churn_data and table customers]
[2024-12-12 15:10:51,510: INFO: etl_main: >>>>>>> stage Data Extraction Stage completed <<<<<<<<

=================x]
[2024-12-12 15:10:51,526: INFO: etl_main: >>>>>>> stage Data Transformation Stage started <<<<<<<<]
[2024-12-12 15:10:51,526: INFO: common: yaml file: D:\repositories\coustomer_churn_prediction_system\config\etl_config.yaml loaded successfully]
[2024-12-12 15:10:51,526: INFO: data_transformation: Schema Validation Passed: Column names and data types match expectations.]
[2024-12-12 15:10:51,526: INFO: data_transformation: No duplicate rows found.]
[2024-12-12 15:11:16,215: INFO: data_transformation: misssing values handled succesfully.]
[2024-12-12 15:11:16,254: INFO: etl_main: >>>>>>> stage Data Transformation Stage completed <<<<<<<<

=================x]
[2024-12-12 15:11:16,254: INFO: etl_main: >>>>>>> stage Data Loading Stage started <<<<<<<<]
[2024-12-12 15:11:16,257: INFO: common: yaml file: D:\repositories\coustomer_churn_prediction_system\config\etl_config.yaml loaded successfully]
[2024-12-12 15:11:16,258: INFO: common: Directory Data created successfully]
[2024-12-12 15:11:16,292: INFO: data_loader: data succesfully loaded to Data/data.csv]
[2024-12-12 15:11:16,292: INFO: etl_main: >>>>>>> stage Data Loading Stage completed <<<<<<<<

=================x]
[2024-12-12 16:18:45,121: INFO: etl_main: >>>>>>> stage Data Extraction Stage started <<<<<<<<]
[2024-12-12 16:18:45,125: INFO: common: yaml file: D:\repositories\coustomer_churn_prediction_system\config\etl_config.yaml loaded successfully]
[2024-12-12 16:18:51,360: INFO: etl_main: >>>>>>> stage Data Extraction Stage completed <<<<<<<<

=================x]
[2024-12-12 16:18:51,370: INFO: etl_main: >>>>>>> stage Data Transformation Stage started <<<<<<<<]
[2024-12-12 16:18:51,370: ERROR: etl_main: DataTransformationPipeline.__init__() got an unexpected keyword argument 'artifact']
Traceback (most recent call last):
  File "D:\repositories\coustomer_churn_prediction_system\etl_main.py", line 19, in <module>
    data_transformation = DataTransformationPipeline(artifact= dataextractionartifact)
TypeError: DataTransformationPipeline.__init__() got an unexpected keyword argument 'artifact'
[2024-12-12 16:19:49,357: INFO: etl_main: >>>>>>> stage Data Extraction Stage started <<<<<<<<]
[2024-12-12 16:19:49,357: INFO: common: yaml file: D:\repositories\coustomer_churn_prediction_system\config\etl_config.yaml loaded successfully]
[2024-12-12 16:23:08,571: INFO: etl_main: >>>>>>> stage Data Extraction Stage started <<<<<<<<]
[2024-12-12 16:23:08,575: INFO: common: yaml file: D:\repositories\coustomer_churn_prediction_system\config\etl_config.yaml loaded successfully]
[2024-12-12 16:23:21,245: INFO: etl_main: >>>>>>> stage Data Extraction Stage completed <<<<<<<<

=================x]
[2024-12-12 16:23:21,245: INFO: etl_main: >>>>>>> stage Data Transformation Stage started <<<<<<<<]
[2024-12-12 16:23:21,245: INFO: common: yaml file: D:\repositories\coustomer_churn_prediction_system\config\etl_config.yaml loaded successfully]
[2024-12-12 16:23:21,245: ERROR: etl_main: Cannot open console input buffer for writing]
Traceback (most recent call last):
  File "D:\repositories\coustomer_churn_prediction_system\src\churn_etl\components\data_transformation.py", line 81, in transform_data
    raw_data_frame  = pd.read_csv(self.config.input_csv)
  File "d:\repositories\coustomer_churn_prediction_system\venv\lib\site-packages\pandas\io\parsers\readers.py", line 1026, in read_csv
    return _read(filepath_or_buffer, kwds)
  File "d:\repositories\coustomer_churn_prediction_system\venv\lib\site-packages\pandas\io\parsers\readers.py", line 620, in _read
    parser = TextFileReader(filepath_or_buffer, **kwds)
  File "d:\repositories\coustomer_churn_prediction_system\venv\lib\site-packages\pandas\io\parsers\readers.py", line 1620, in __init__
    self._engine = self._make_engine(f, self.engine)
  File "d:\repositories\coustomer_churn_prediction_system\venv\lib\site-packages\pandas\io\parsers\readers.py", line 1880, in _make_engine
    self.handles = get_handle(
  File "d:\repositories\coustomer_churn_prediction_system\venv\lib\site-packages\pandas\io\common.py", line 873, in get_handle
    handle = open(
FileNotFoundError: [Errno 2] No such file or directory: 'artifacts/data_Extracting/raw_data.csv'

During handling of the above exception, another exception occurred:

Traceback (most recent call last):
  File "D:\repositories\coustomer_churn_prediction_system\etl_main.py", line 20, in <module>
    data_transformation.initiate_data_Transformation()
  File "D:\repositories\coustomer_churn_prediction_system\src\churn_etl\pipeline\data_transformation_pipeline.py", line 16, in initiate_data_Transformation
    raise e
  File "D:\repositories\coustomer_churn_prediction_system\src\churn_etl\pipeline\data_transformation_pipeline.py", line 14, in initiate_data_Transformation
    data_Transformation.transform_data()
  File "D:\repositories\coustomer_churn_prediction_system\src\churn_etl\components\data_transformation.py", line 96, in transform_data
    with open(self.transformation_status, "w") as file:
ValueError: Cannot open console input buffer for writing
[2024-12-12 16:26:39,874: INFO: etl_main: >>>>>>> stage Data Extraction Stage started <<<<<<<<]
[2024-12-12 16:26:39,881: INFO: common: yaml file: D:\repositories\coustomer_churn_prediction_system\config\etl_config.yaml loaded successfully]
[2024-12-12 16:26:39,881: INFO: common: Directory ETL_artifacts created successfully]
[2024-12-12 16:26:39,881: ERROR: etl_main: "'ConfigBox' object has no attribute 'root_dir'"]
Traceback (most recent call last):
  File "box\\box.py", line 593, in box.box.Box.__getitem__
KeyError: 'root_dir'

The above exception was the direct cause of the following exception:

Traceback (most recent call last):
  File "box\\box.py", line 632, in box.box.Box.__getattr__
  File "box\\box.py", line 620, in box.box.Box.__getitem__
box.exceptions.BoxKeyError: "'root_dir'"

During handling of the above exception, another exception occurred:

Traceback (most recent call last):
  File "box\\box.py", line 634, in box.box.Box.__getattr__
AttributeError: 'ConfigBox' object has no attribute 'root_dir'

The above exception was the direct cause of the following exception:

Traceback (most recent call last):
  File "box\\config_box.py", line 29, in box.config_box.ConfigBox.__getattr__
  File "box\\box.py", line 648, in box.box.Box.__getattr__
box.exceptions.BoxKeyError: "'ConfigBox' object has no attribute 'root_dir'"

During handling of the above exception, another exception occurred:

Traceback (most recent call last):
  File "box\\box.py", line 593, in box.box.Box.__getitem__
KeyError: 'root_dir'

The above exception was the direct cause of the following exception:

Traceback (most recent call last):
  File "box\\box.py", line 632, in box.box.Box.__getattr__
  File "box\\box.py", line 620, in box.box.Box.__getitem__
box.exceptions.BoxKeyError: "'root_dir'"

During handling of the above exception, another exception occurred:

Traceback (most recent call last):
  File "box\\box.py", line 634, in box.box.Box.__getattr__
AttributeError: 'ConfigBox' object has no attribute 'root_dir'

The above exception was the direct cause of the following exception:

Traceback (most recent call last):
  File "D:\repositories\coustomer_churn_prediction_system\etl_main.py", line 10, in <module>
    data_extraction.initiate_data_extraction()
  File "D:\repositories\coustomer_churn_prediction_system\src\churn_etl\pipeline\data_extraction_pipeline.py", line 16, in initiate_data_extraction
    raise e
  File "D:\repositories\coustomer_churn_prediction_system\src\churn_etl\pipeline\data_extraction_pipeline.py", line 12, in initiate_data_extraction
    data_extraction_config = config.get_data_extraction_config()
  File "D:\repositories\coustomer_churn_prediction_system\src\churn_etl\config\configuration.py", line 16, in get_data_extraction_config
    create_directories([self.config.root_dir])
  File "box\\config_box.py", line 31, in box.config_box.ConfigBox.__getattr__
  File "box\\box.py", line 648, in box.box.Box.__getattr__
box.exceptions.BoxKeyError: "'ConfigBox' object has no attribute 'root_dir'"
[2024-12-12 16:27:32,026: INFO: etl_main: >>>>>>> stage Data Extraction Stage started <<<<<<<<]
[2024-12-12 16:27:32,030: INFO: common: yaml file: D:\repositories\coustomer_churn_prediction_system\config\etl_config.yaml loaded successfully]
[2024-12-12 16:27:32,030: INFO: common: Directory ETL_artifacts created successfully]
[2024-12-12 16:27:32,031: INFO: common: Directory ETL_artifacts/data_Extracting created successfully]
[2024-12-12 16:29:22,107: INFO: etl_main: >>>>>>> stage Data Extraction Stage started <<<<<<<<]
[2024-12-12 16:29:22,110: INFO: common: yaml file: D:\repositories\coustomer_churn_prediction_system\config\etl_config.yaml loaded successfully]
[2024-12-12 16:29:22,110: INFO: common: Directory ETL_artifacts created successfully]
[2024-12-12 16:29:22,111: INFO: common: Directory ETL_artifacts/data_Extracting created successfully]
[2024-12-12 16:29:29,851: INFO: data_extracting: data succesfully fetched from customer_churn_data and table customers]
[2024-12-12 16:29:29,851: INFO: etl_main: >>>>>>> stage Data Extraction Stage completed <<<<<<<<

=================x]
[2024-12-12 16:29:29,851: INFO: etl_main: >>>>>>> stage Data Transformation Stage started <<<<<<<<]
[2024-12-12 16:29:29,855: INFO: common: yaml file: D:\repositories\coustomer_churn_prediction_system\config\etl_config.yaml loaded successfully]
[2024-12-12 16:29:29,856: INFO: common: Directory ETL_artifacts created successfully]
[2024-12-12 16:29:29,856: INFO: common: Directory ETL_artifacts/data_transformation created successfully]
[2024-12-12 16:29:29,868: INFO: data_transformation: Column mismatch. Expected columns: {'CustomerID': 'int64', 'Churn': 'int64', 'Tenure': 'float64', 'PreferredLoginDevice': 'object', 'CityTier': 'int64', 'WarehouseToHome': 'float64', 'PreferredPaymentMode': 'object', 'Gender': 'object', 'HourSpendOnApp': 'float64', 'NumberOfDeviceRegistered': 'int64', 'PreferedOrderCat': 'object', 'SatisfactionScore': 'int64', 'MaritalStatus': 'object', 'NumberOfAddress': 'int64', 'Complain': 'int64', 'OrderAmountHikeFromlastYear': 'float64', 'CouponUsed': 'float64', 'OrderCount': 'float64', 'DaySinceLastOrder': 'float64', 'CashbackAmount': 'float64'}, Actual columns: Index(['Unnamed: 0', 'CustomerID', 'Churn', 'Tenure', 'PreferredLoginDevice',
       'CityTier', 'WarehouseToHome', 'PreferredPaymentMode', 'Gender',
       'HourSpendOnApp', 'NumberOfDeviceRegistered', 'PreferedOrderCat',
       'SatisfactionScore', 'MaritalStatus', 'NumberOfAddress', 'Complain',
       'OrderAmountHikeFromlastYear', 'CouponUsed', 'OrderCount',
       'DaySinceLastOrder', 'CashbackAmount'],
      dtype='object')]
[2024-12-12 16:29:29,869: INFO: etl_main: >>>>>>> stage Data Transformation Stage completed <<<<<<<<

=================x]
[2024-12-12 16:29:29,869: INFO: etl_main: >>>>>>> stage Data Loading Stage started <<<<<<<<]
[2024-12-12 16:29:29,872: INFO: common: yaml file: D:\repositories\coustomer_churn_prediction_system\config\etl_config.yaml loaded successfully]
[2024-12-12 16:29:29,873: INFO: common: Directory ETL_artifacts created successfully]
[2024-12-12 16:29:29,873: INFO: common: Directory Data created successfully]
[2024-12-12 16:29:29,873: ERROR: data_loader: Error while loading data: [Errno 2] No such file or directory: 'ETL_artifacts/data_transformation/transformed_data.csv']
[2024-12-12 16:29:29,873: INFO: etl_main: >>>>>>> stage Data Loading Stage completed <<<<<<<<

=================x]
[2024-12-12 16:33:38,493: INFO: etl_main: >>>>>>> stage Data Extraction Stage started <<<<<<<<]
[2024-12-12 16:33:38,498: INFO: common: yaml file: D:\repositories\coustomer_churn_prediction_system\config\etl_config.yaml loaded successfully]
[2024-12-12 16:33:38,499: INFO: common: Directory ETL_artifacts created successfully]
[2024-12-12 16:33:38,499: INFO: common: Directory ETL_artifacts/data_Extracting created successfully]
[2024-12-12 16:33:51,380: INFO: data_extracting: data succesfully fetched from customer_churn_data and table customers]
[2024-12-12 16:33:51,381: INFO: etl_main: >>>>>>> stage Data Extraction Stage completed <<<<<<<<

=================x]
[2024-12-12 16:33:51,381: INFO: etl_main: >>>>>>> stage Data Transformation Stage started <<<<<<<<]
[2024-12-12 16:33:51,383: INFO: common: yaml file: D:\repositories\coustomer_churn_prediction_system\config\etl_config.yaml loaded successfully]
[2024-12-12 16:33:51,383: INFO: common: Directory ETL_artifacts created successfully]
[2024-12-12 16:33:51,383: INFO: common: Directory ETL_artifacts/data_transformation created successfully]
[2024-12-12 16:33:51,393: INFO: data_transformation: Schema Validation Passed: Column names and data types match expectations.]
[2024-12-12 16:33:51,397: INFO: data_transformation: No duplicate rows found.]
[2024-12-12 16:34:17,079: INFO: data_transformation: misssing values handled succesfully.]
[2024-12-12 16:34:17,102: ERROR: etl_main: Cannot open console input buffer for writing]
Traceback (most recent call last):
  File "D:\repositories\coustomer_churn_prediction_system\src\churn_etl\components\data_transformation.py", line 89, in transform_data
    transformed_data.to_csv(self.config.transformation_output_csv, index=False)
  File "d:\repositories\coustomer_churn_prediction_system\venv\lib\site-packages\pandas\util\_decorators.py", line 333, in wrapper
    return func(*args, **kwargs)
  File "d:\repositories\coustomer_churn_prediction_system\venv\lib\site-packages\pandas\core\generic.py", line 3967, in to_csv
    return DataFrameRenderer(formatter).to_csv(
  File "d:\repositories\coustomer_churn_prediction_system\venv\lib\site-packages\pandas\io\formats\format.py", line 1014, in to_csv
    csv_formatter.save()
  File "d:\repositories\coustomer_churn_prediction_system\venv\lib\site-packages\pandas\io\formats\csvs.py", line 251, in save
    with get_handle(
  File "d:\repositories\coustomer_churn_prediction_system\venv\lib\site-packages\pandas\io\common.py", line 749, in get_handle
    check_parent_directory(str(handle))
  File "d:\repositories\coustomer_churn_prediction_system\venv\lib\site-packages\pandas\io\common.py", line 616, in check_parent_directory
    raise OSError(rf"Cannot save file into a non-existent directory: '{parent}'")
OSError: Cannot save file into a non-existent directory: 'ETL_artifacts\data_tranformation'

During handling of the above exception, another exception occurred:

Traceback (most recent call last):
  File "D:\repositories\coustomer_churn_prediction_system\etl_main.py", line 20, in <module>
    data_transformation.initiate_data_Transformation()
  File "D:\repositories\coustomer_churn_prediction_system\src\churn_etl\pipeline\data_transformation_pipeline.py", line 16, in initiate_data_Transformation
    raise e
  File "D:\repositories\coustomer_churn_prediction_system\src\churn_etl\pipeline\data_transformation_pipeline.py", line 14, in initiate_data_Transformation
    data_Transformation.transform_data()
  File "D:\repositories\coustomer_churn_prediction_system\src\churn_etl\components\data_transformation.py", line 96, in transform_data
    with open(self.transformation_status, "w") as file:
ValueError: Cannot open console input buffer for writing
[2024-12-12 16:41:12,164: INFO: etl_main: >>>>>>> stage Data Extraction Stage started <<<<<<<<]
[2024-12-12 16:41:12,171: INFO: common: yaml file: D:\repositories\coustomer_churn_prediction_system\config\etl_config.yaml loaded successfully]
[2024-12-12 16:41:12,171: INFO: common: Directory ETL_artifacts created successfully]
[2024-12-12 16:41:12,171: INFO: common: Directory ETL_artifacts/data_Extracting created successfully]
[2024-12-12 16:41:36,696: INFO: data_extracting: data succesfully fetched from customer_churn_data and table customers]
[2024-12-12 16:41:36,696: INFO: etl_main: >>>>>>> stage Data Extraction Stage completed <<<<<<<<

=================x]
[2024-12-12 16:41:36,696: INFO: etl_main: >>>>>>> stage Data Transformation Stage started <<<<<<<<]
[2024-12-12 16:41:36,696: INFO: common: yaml file: D:\repositories\coustomer_churn_prediction_system\config\etl_config.yaml loaded successfully]
[2024-12-12 16:41:36,696: INFO: common: Directory ETL_artifacts created successfully]
[2024-12-12 16:41:36,707: INFO: common: Directory ETL_artifacts/data_transformation created successfully]
[2024-12-12 16:41:36,718: INFO: data_transformation: Schema Validation Passed: Column names and data types match expectations.]
[2024-12-12 16:41:36,721: INFO: data_transformation: No duplicate rows found.]
[2024-12-12 16:42:02,577: INFO: data_transformation: misssing values handled succesfully.]
[2024-12-12 16:42:02,641: INFO: etl_main: >>>>>>> stage Data Transformation Stage completed <<<<<<<<

=================x]
[2024-12-12 16:42:02,641: INFO: etl_main: >>>>>>> stage Data Loading Stage started <<<<<<<<]
[2024-12-12 16:42:02,645: INFO: common: yaml file: D:\repositories\coustomer_churn_prediction_system\config\etl_config.yaml loaded successfully]
[2024-12-12 16:42:02,645: INFO: common: Directory ETL_artifacts created successfully]
[2024-12-12 16:42:02,646: INFO: common: Directory Data created successfully]
[2024-12-12 16:42:02,690: INFO: data_loader: data succesfully loaded to Data/data.csv]
[2024-12-12 16:42:02,691: INFO: etl_main: >>>>>>> stage Data Loading Stage completed <<<<<<<<

=================x]
[2024-12-12 17:15:50,302: INFO: etl_main: >>>>>>> stage extract started <<<<<<<<]
[2024-12-12 17:15:50,305: INFO: common: yaml file: D:\repositories\coustomer_churn_prediction_system\config\etl_config.yaml loaded successfully]
[2024-12-12 17:15:50,306: INFO: common: Directory ETL_artifacts created successfully]
[2024-12-12 17:15:50,306: INFO: common: Directory ETL_artifacts/data_Extracting created successfully]
[2024-12-12 17:16:03,859: INFO: data_extracting: data succesfully fetched from customer_churn_data and table customers]
[2024-12-12 17:16:03,861: INFO: etl_main: >>>>>>> stage extract completed <<<<<<<<

=================x]
[2024-12-12 17:16:06,269: INFO: etl_main: >>>>>>> stage transform started <<<<<<<<]
[2024-12-12 17:16:06,277: INFO: common: yaml file: D:\repositories\coustomer_churn_prediction_system\config\etl_config.yaml loaded successfully]
[2024-12-12 17:16:06,278: INFO: common: Directory ETL_artifacts created successfully]
[2024-12-12 17:16:06,278: INFO: common: Directory ETL_artifacts/data_transformation created successfully]
[2024-12-12 17:16:06,278: ERROR: etl_main: Cannot open console input buffer for writing]
Traceback (most recent call last):
  File "D:\repositories\coustomer_churn_prediction_system\src\churn_etl\components\data_transformation.py", line 81, in transform_data
    raw_data_frame  = pd.read_csv(self.config.input_csv)
  File "d:\repositories\coustomer_churn_prediction_system\venv\lib\site-packages\pandas\io\parsers\readers.py", line 1026, in read_csv
    return _read(filepath_or_buffer, kwds)
  File "d:\repositories\coustomer_churn_prediction_system\venv\lib\site-packages\pandas\io\parsers\readers.py", line 620, in _read
    parser = TextFileReader(filepath_or_buffer, **kwds)
  File "d:\repositories\coustomer_churn_prediction_system\venv\lib\site-packages\pandas\io\parsers\readers.py", line 1620, in __init__
    self._engine = self._make_engine(f, self.engine)
  File "d:\repositories\coustomer_churn_prediction_system\venv\lib\site-packages\pandas\io\parsers\readers.py", line 1880, in _make_engine
    self.handles = get_handle(
  File "d:\repositories\coustomer_churn_prediction_system\venv\lib\site-packages\pandas\io\common.py", line 873, in get_handle
    handle = open(
FileNotFoundError: [Errno 2] No such file or directory: 'ETL_artifacts/data_Extracting/raw_data.csv'

During handling of the above exception, another exception occurred:

Traceback (most recent call last):
  File "D:\repositories\coustomer_churn_prediction_system\etl_main.py", line 16, in run_stage
    data_transformation.initiate_data_Transformation()
  File "D:\repositories\coustomer_churn_prediction_system\src\churn_etl\pipeline\data_transformation_pipeline.py", line 16, in initiate_data_Transformation
    raise e
  File "D:\repositories\coustomer_churn_prediction_system\src\churn_etl\pipeline\data_transformation_pipeline.py", line 14, in initiate_data_Transformation
    data_Transformation.transform_data()
  File "D:\repositories\coustomer_churn_prediction_system\src\churn_etl\components\data_transformation.py", line 96, in transform_data
    with open(self.transformation_status, "w") as file:
ValueError: Cannot open console input buffer for writing
[2024-12-12 19:25:08,098: INFO: etl_main: >>>>>>> stage transform started <<<<<<<<]
[2024-12-12 19:25:08,103: INFO: common: yaml file: D:\repositories\coustomer_churn_prediction_system\config\etl_config.yaml loaded successfully]
[2024-12-12 19:25:08,104: INFO: common: Directory ETL_artifacts created successfully]
[2024-12-12 19:25:08,104: INFO: common: Directory ETL_artifacts/data_transformation created successfully]
[2024-12-12 19:25:08,124: INFO: data_transformation: Schema Validation Passed: Column names and data types match expectations.]
[2024-12-12 19:25:08,130: INFO: data_transformation: No duplicate rows found.]
[2024-12-12 19:25:39,971: INFO: data_transformation: misssing values handled succesfully.]
[2024-12-12 19:25:40,060: INFO: etl_main: >>>>>>> stage transform completed <<<<<<<<

=================x]
[2024-12-12 19:25:41,838: INFO: etl_main: >>>>>>> stage load started <<<<<<<<]
[2024-12-12 19:25:41,844: INFO: common: yaml file: D:\repositories\coustomer_churn_prediction_system\config\etl_config.yaml loaded successfully]
[2024-12-12 19:25:41,844: INFO: common: Directory ETL_artifacts created successfully]
[2024-12-12 19:25:41,844: INFO: common: Directory Data created successfully]
[2024-12-12 19:25:41,905: INFO: data_loader: data succesfully loaded to Data/data.csv]
[2024-12-12 19:25:41,905: INFO: etl_main: >>>>>>> stage load completed <<<<<<<<

=================x]
[2024-12-12 19:28:34,994: INFO: etl_main: >>>>>>> stage load started <<<<<<<<]
[2024-12-12 19:28:34,998: INFO: common: yaml file: D:\repositories\coustomer_churn_prediction_system\config\etl_config.yaml loaded successfully]
[2024-12-12 19:28:34,998: INFO: common: Directory ETL_artifacts created successfully]
[2024-12-12 19:28:34,998: INFO: common: Directory Data created successfully]
[2024-12-12 19:28:35,063: INFO: data_loader: data succesfully loaded to Data/data.csv]
[2024-12-12 19:28:35,063: INFO: etl_main: >>>>>>> stage load completed <<<<<<<<

=================x]
[2024-12-13 16:10:45,068: INFO: training_main: >>>>>>> stage Data ingestion Stage started <<<<<<<<]
[2024-12-13 16:10:45,069: INFO: common: yaml file: D:\repositories\coustomer_churn_prediction_system\config\training_config.yaml loaded successfully]
[2024-12-13 16:10:45,069: INFO: common: Directory Training_artifacts created successfully]
[2024-12-13 16:10:45,084: INFO: common: Directory Training_artifacts/data_ingestion created successfully]
[2024-12-13 16:10:45,186: INFO: data_ingestion: Ingestion completed. Data loaded to csv]
[2024-12-13 16:10:45,186: INFO: data_ingestion_pipeline: Data ingestion completed successfully]
[2024-12-13 16:10:45,186: INFO: training_main: >>>>>>> stage Data ingestion Stage completed <<<<<<<<

=================x]
[2024-12-13 16:42:36,037: INFO: training_main: >>>>>>> stage Data Validation Stage started <<<<<<<<]
[2024-12-13 16:42:36,049: INFO: common: yaml file: D:\repositories\coustomer_churn_prediction_system\config\training_config.yaml loaded successfully]
[2024-12-13 16:42:36,052: INFO: common: Directory Training_artifacts created successfully]
[2024-12-13 16:42:36,052: INFO: common: Directory Training_artifacts/data_validation created successfully]
[2024-12-13 16:42:36,075: ERROR: data_validation: Column 'CustomerID' has incorrect data type. Expected int64, got float64]
[2024-12-13 16:42:36,075: ERROR: data_validation: Column 'Churn' has incorrect data type. Expected int64, got float64]
[2024-12-13 16:42:36,075: ERROR: data_validation: Column 'CityTier' has incorrect data type. Expected int64, got float64]
[2024-12-13 16:42:36,076: ERROR: data_validation: Column 'NumberOfDeviceRegistered' has incorrect data type. Expected int64, got float64]
[2024-12-13 16:42:36,076: ERROR: data_validation: Column 'SatisfactionScore' has incorrect data type. Expected int64, got float64]
[2024-12-13 16:42:36,076: ERROR: data_validation: Column 'NumberOfAddress' has incorrect data type. Expected int64, got float64]
[2024-12-13 16:42:36,076: ERROR: data_validation: Column 'Complain' has incorrect data type. Expected int64, got float64]
[2024-12-13 16:42:36,083: ERROR: data_validation: Column 'PreferredLoginDevice' contains invalid values: ['Mobile Phone' 'Phone' 'Computer']]
[2024-12-13 16:42:36,089: ERROR: data_validation: Schema Validation Failed. See errors for details.]
[2024-12-13 16:42:36,091: INFO: data_validation_pipelien: Data Validation completed successfully]
[2024-12-13 16:42:36,093: INFO: training_main: >>>>>>> stage Data Validation Stage completed <<<<<<<<

=================x]
[2024-12-13 16:50:34,008: INFO: training_main: >>>>>>> stage Data Validation Stage started <<<<<<<<]
[2024-12-13 16:50:34,018: INFO: common: yaml file: D:\repositories\coustomer_churn_prediction_system\config\training_config.yaml loaded successfully]
[2024-12-13 16:50:34,018: INFO: common: Directory Training_artifacts created successfully]
[2024-12-13 16:50:34,018: INFO: common: Directory Training_artifacts/data_validation created successfully]
[2024-12-13 16:50:34,042: INFO: data_validation: Schema Validation Passed: Column names, data types, and constraints match expectations.]
[2024-12-13 16:50:34,042: INFO: data_validation_pipelien: Data Validation completed successfully]
[2024-12-13 16:50:34,042: INFO: training_main: >>>>>>> stage Data Validation Stage completed <<<<<<<<

=================x]
[2024-12-13 16:55:55,791: INFO: training_main: >>>>>>> stage Data Validation Stage started <<<<<<<<]
[2024-12-13 16:55:55,803: INFO: common: yaml file: D:\repositories\coustomer_churn_prediction_system\config\training_config.yaml loaded successfully]
[2024-12-13 16:55:55,804: INFO: common: Directory Training_artifacts created successfully]
[2024-12-13 16:55:55,805: INFO: common: Directory Training_artifacts/data_validation created successfully]
[2024-12-13 16:55:55,834: INFO: data_validation: Schema Validation Passed: Column names, data types, and constraints match expectations.]
[2024-12-13 16:55:55,834: INFO: data_validation_pipelien: Data Validation completed successfully]
[2024-12-13 16:55:55,834: INFO: training_main: >>>>>>> stage Data Validation Stage completed <<<<<<<<

=================x]
[2024-12-13 17:52:16,852: INFO: training_main: >>>>>>> stage Data Transformation Stage started <<<<<<<<]
[2024-12-13 17:52:16,864: INFO: common: yaml file: D:\repositories\coustomer_churn_prediction_system\config\training_config.yaml loaded successfully]
[2024-12-13 17:52:16,864: INFO: common: Directory Training_artifacts created successfully]
[2024-12-13 17:52:16,864: INFO: common: Directory Training_artifacts/data_transformation created successfully]
[2024-12-13 17:52:16,919: ERROR: data_transformation_pipeline: Error in initiating data Transformation pipeline: 'NoneType' object has no attribute 'select_dtypes']
[2024-12-13 17:52:16,919: ERROR: training_main: 'NoneType' object has no attribute 'select_dtypes']
Traceback (most recent call last):
  File "D:\repositories\coustomer_churn_prediction_system\training_main.py", line 31, in <module>
    data_transformation_pipeline.initiate_data_transformation()
  File "D:\repositories\coustomer_churn_prediction_system\src\churn_train\pipeline\data_transformation_pipeline.py", line 15, in initiate_data_transformation
    data_transformer.transform_data()
  File "D:\repositories\coustomer_churn_prediction_system\src\churn_train\components\data_transformation.py", line 55, in transform_data
    features = self.scale_numerical_features(features)
  File "D:\repositories\coustomer_churn_prediction_system\src\churn_train\components\data_transformation.py", line 33, in scale_numerical_features
    numerical_cols = features.select_dtypes(include=['float64', 'int64']).columns
AttributeError: 'NoneType' object has no attribute 'select_dtypes'
[2024-12-13 17:53:31,693: INFO: training_main: >>>>>>> stage Data Transformation Stage started <<<<<<<<]
[2024-12-13 17:53:31,704: INFO: common: yaml file: D:\repositories\coustomer_churn_prediction_system\config\training_config.yaml loaded successfully]
[2024-12-13 17:53:31,704: INFO: common: Directory Training_artifacts created successfully]
[2024-12-13 17:53:31,704: INFO: common: Directory Training_artifacts/data_transformation created successfully]
[2024-12-13 17:53:31,750: ERROR: data_transformation_pipeline: Error in initiating data Transformation pipeline: 'numpy.ndarray' object has no attribute 'select_dtypes']
[2024-12-13 17:53:31,750: ERROR: training_main: 'numpy.ndarray' object has no attribute 'select_dtypes']
Traceback (most recent call last):
  File "D:\repositories\coustomer_churn_prediction_system\training_main.py", line 31, in <module>
    data_transformation_pipeline.initiate_data_transformation()
  File "D:\repositories\coustomer_churn_prediction_system\src\churn_train\pipeline\data_transformation_pipeline.py", line 15, in initiate_data_transformation
    data_transformer.transform_data()
  File "D:\repositories\coustomer_churn_prediction_system\src\churn_train\components\data_transformation.py", line 57, in transform_data
    features = self.scale_numerical_features(features)
  File "D:\repositories\coustomer_churn_prediction_system\src\churn_train\components\data_transformation.py", line 35, in scale_numerical_features
    numerical_cols = features.select_dtypes(include=['float64', 'int64']).columns
AttributeError: 'numpy.ndarray' object has no attribute 'select_dtypes'
[2024-12-13 19:15:58,969: INFO: _client: HTTP Request: POST https://dagshub.com/login/oauth/middleman "HTTP/1.1 200 OK"]
[2024-12-13 19:15:59,520: INFO: _client: HTTP Request: POST https://dagshub.com/login/oauth/access_token "HTTP/1.1 200 OK"]
[2024-12-13 19:16:00,076: INFO: _client: HTTP Request: GET https://dagshub.com/api/v1/user "HTTP/1.1 200 OK"]
[2024-12-13 19:16:00,082: INFO: helpers: Accessing as saivardhan4694]
[2024-12-13 19:16:00,787: INFO: _client: HTTP Request: GET https://dagshub.com/api/v1/repos/saivardhan4694/coustomer_churn_prediction_system "HTTP/1.1 200 OK"]
[2024-12-13 19:16:01,603: INFO: _client: HTTP Request: GET https://dagshub.com/api/v1/user "HTTP/1.1 200 OK"]
[2024-12-13 19:16:01,608: INFO: helpers: Initialized MLflow to track repo "saivardhan4694/coustomer_churn_prediction_system"]
[2024-12-13 19:16:01,608: INFO: helpers: Repository saivardhan4694/coustomer_churn_prediction_system initialized!]
[2024-12-13 19:30:05,134: INFO: _client: HTTP Request: GET https://dagshub.com/api/v1/user "HTTP/1.1 200 OK"]
[2024-12-13 19:30:05,134: INFO: helpers: Accessing as saivardhan4694]
[2024-12-13 19:30:05,684: INFO: _client: HTTP Request: GET https://dagshub.com/api/v1/repos/saivardhan4694/coustomer_churn_prediction_system "HTTP/1.1 200 OK"]
[2024-12-13 19:30:06,168: INFO: _client: HTTP Request: GET https://dagshub.com/api/v1/user "HTTP/1.1 200 OK"]
[2024-12-13 19:30:06,168: INFO: helpers: Initialized MLflow to track repo "saivardhan4694/coustomer_churn_prediction_system"]
[2024-12-13 19:30:06,168: INFO: helpers: Repository saivardhan4694/coustomer_churn_prediction_system initialized!]
[2024-12-13 19:33:38,776: INFO: _client: HTTP Request: GET https://dagshub.com/api/v1/user "HTTP/1.1 200 OK"]
[2024-12-13 19:33:38,788: INFO: helpers: Accessing as saivardhan4694]
[2024-12-13 19:33:39,389: INFO: _client: HTTP Request: GET https://dagshub.com/api/v1/repos/saivardhan4694/coustomer_churn_prediction_system "HTTP/1.1 200 OK"]
[2024-12-13 19:33:39,852: INFO: _client: HTTP Request: GET https://dagshub.com/api/v1/user "HTTP/1.1 200 OK"]
[2024-12-13 19:33:39,852: INFO: helpers: Initialized MLflow to track repo "saivardhan4694/coustomer_churn_prediction_system"]
[2024-12-13 19:33:39,852: INFO: helpers: Repository saivardhan4694/coustomer_churn_prediction_system initialized!]
[2024-12-13 23:11:41,750: INFO: training_main: >>>>>>> stage Model training Stage started <<<<<<<<]
[2024-12-13 23:11:41,768: INFO: common: yaml file: D:\repositories\coustomer_churn_prediction_system\config\training_config.yaml loaded successfully]
[2024-12-13 23:11:41,768: INFO: common: Directory Training_artifacts created successfully]
[2024-12-13 23:11:42,268: INFO: _client: HTTP Request: GET https://dagshub.com/api/v1/user "HTTP/1.1 200 OK"]
[2024-12-13 23:11:42,280: INFO: helpers: Accessing as saivardhan4694]
[2024-12-13 23:11:42,804: INFO: _client: HTTP Request: GET https://dagshub.com/api/v1/repos/saivardhan4694/coustomer_churn_prediction_system "HTTP/1.1 200 OK"]
[2024-12-13 23:11:43,303: INFO: _client: HTTP Request: GET https://dagshub.com/api/v1/user "HTTP/1.1 200 OK"]
[2024-12-13 23:11:43,319: INFO: helpers: Initialized MLflow to track repo "saivardhan4694/coustomer_churn_prediction_system"]
[2024-12-13 23:11:43,319: INFO: helpers: Repository saivardhan4694/coustomer_churn_prediction_system initialized!]
[2024-12-13 23:12:00,143: INFO: model_training: model Churn_KNN_Model loaded succesfully.]
[2024-12-13 23:12:00,143: INFO: model_training: initiating Churn_KNN_Model training]
[2024-12-13 23:12:16,899: ERROR: model_training_pipeline: Error in initiating model training pipeline: register_model() missing 1 required positional argument: 'model_uri']
[2024-12-13 23:12:16,900: ERROR: training_main: register_model() missing 1 required positional argument: 'model_uri']
Traceback (most recent call last):
  File "D:\repositories\coustomer_churn_prediction_system\training_main.py", line 40, in <module>
    model_trianing_pipeline.initiate_model_training()
  File "D:\repositories\coustomer_churn_prediction_system\src\churn_train\pipeline\model_training_pipeline.py", line 15, in initiate_model_training
    model_trainer.train_models()
  File "D:\repositories\coustomer_churn_prediction_system\src\churn_train\components\model_training.py", line 177, in train_models
    self.model_trainer(model_name=str(model),
  File "D:\repositories\coustomer_churn_prediction_system\src\churn_train\components\model_training.py", line 142, in model_trainer
    mlflow.register_model(name=model_name)
TypeError: register_model() missing 1 required positional argument: 'model_uri'
[2024-12-13 23:17:46,758: INFO: training_main: >>>>>>> stage Model training Stage started <<<<<<<<]
[2024-12-13 23:17:46,758: INFO: common: yaml file: D:\repositories\coustomer_churn_prediction_system\config\training_config.yaml loaded successfully]
[2024-12-13 23:17:46,771: INFO: common: Directory Training_artifacts created successfully]
[2024-12-13 23:17:47,265: INFO: _client: HTTP Request: GET https://dagshub.com/api/v1/user "HTTP/1.1 200 OK"]
[2024-12-13 23:17:47,279: INFO: helpers: Accessing as saivardhan4694]
[2024-12-13 23:17:47,799: INFO: _client: HTTP Request: GET https://dagshub.com/api/v1/repos/saivardhan4694/coustomer_churn_prediction_system "HTTP/1.1 200 OK"]
[2024-12-13 23:17:48,284: INFO: _client: HTTP Request: GET https://dagshub.com/api/v1/user "HTTP/1.1 200 OK"]
[2024-12-13 23:17:48,284: INFO: helpers: Initialized MLflow to track repo "saivardhan4694/coustomer_churn_prediction_system"]
[2024-12-13 23:17:48,284: INFO: helpers: Repository saivardhan4694/coustomer_churn_prediction_system initialized!]
[2024-12-13 23:17:59,068: INFO: model_training: model Churn_KNN_Model loaded succesfully.]
[2024-12-13 23:17:59,068: INFO: model_training: initiating Churn_KNN_Model training]
[2024-12-13 23:18:16,330: INFO: model_training: Churn_KNN_Model training completed. metrics and artifacts are loaded to MLflow experiment KNN_Experiment]
[2024-12-13 23:18:27,448: INFO: model_training: model churn_logistic_reg_model loaded succesfully.]
[2024-12-13 23:18:27,448: INFO: model_training: initiating churn_logistic_reg_model training]
[2024-12-13 23:18:46,336: INFO: model_training: churn_logistic_reg_model training completed. metrics and artifacts are loaded to MLflow experiment Logistic_Regression_Experiment]
[2024-12-13 23:18:46,336: INFO: model_training_pipeline: model training completed successfully]
[2024-12-13 23:18:46,338: INFO: training_main: >>>>>>> stage Model training Stage completed <<<<<<<<

=================x]
[2024-12-13 23:20:53,689: INFO: training_main: >>>>>>> stage Model training Stage started <<<<<<<<]
[2024-12-13 23:20:53,689: INFO: common: yaml file: D:\repositories\coustomer_churn_prediction_system\config\training_config.yaml loaded successfully]
[2024-12-13 23:20:53,689: INFO: common: Directory Training_artifacts created successfully]
[2024-12-13 23:20:54,239: INFO: _client: HTTP Request: GET https://dagshub.com/api/v1/user "HTTP/1.1 200 OK"]
[2024-12-13 23:20:54,239: INFO: helpers: Accessing as saivardhan4694]
[2024-12-13 23:20:54,755: INFO: _client: HTTP Request: GET https://dagshub.com/api/v1/repos/saivardhan4694/coustomer_churn_prediction_system "HTTP/1.1 200 OK"]
[2024-12-13 23:20:55,237: INFO: _client: HTTP Request: GET https://dagshub.com/api/v1/user "HTTP/1.1 200 OK"]
[2024-12-13 23:20:55,240: INFO: helpers: Initialized MLflow to track repo "saivardhan4694/coustomer_churn_prediction_system"]
[2024-12-13 23:20:55,240: INFO: helpers: Repository saivardhan4694/coustomer_churn_prediction_system initialized!]
[2024-12-13 23:21:00,381: INFO: model_training: model Churn_KNN_Model loaded succesfully.]
[2024-12-13 23:21:00,381: INFO: model_training: initiating Churn_KNN_Model training]
[2024-12-13 23:21:17,043: ERROR: model_training_pipeline: Error in initiating model training pipeline: register_model() missing 1 required positional argument: 'name']
[2024-12-13 23:21:17,043: ERROR: training_main: register_model() missing 1 required positional argument: 'name']
Traceback (most recent call last):
  File "D:\repositories\coustomer_churn_prediction_system\training_main.py", line 40, in <module>
    model_trianing_pipeline.initiate_model_training()
  File "D:\repositories\coustomer_churn_prediction_system\src\churn_train\pipeline\model_training_pipeline.py", line 15, in initiate_model_training
    model_trainer.train_models()
  File "D:\repositories\coustomer_churn_prediction_system\src\churn_train\components\model_training.py", line 179, in train_models
    self.model_trainer(model_name=str(model),
  File "D:\repositories\coustomer_churn_prediction_system\src\churn_train\components\model_training.py", line 144, in model_trainer
    mlflow.register_model(model_uri=model_uri)
TypeError: register_model() missing 1 required positional argument: 'name'
[2024-12-13 23:21:56,356: INFO: training_main: >>>>>>> stage Model training Stage started <<<<<<<<]
[2024-12-13 23:21:56,356: INFO: common: yaml file: D:\repositories\coustomer_churn_prediction_system\config\training_config.yaml loaded successfully]
[2024-12-13 23:21:56,356: INFO: common: Directory Training_artifacts created successfully]
[2024-12-13 23:21:56,855: INFO: _client: HTTP Request: GET https://dagshub.com/api/v1/user "HTTP/1.1 200 OK"]
[2024-12-13 23:21:56,858: INFO: helpers: Accessing as saivardhan4694]
[2024-12-13 23:21:57,360: INFO: _client: HTTP Request: GET https://dagshub.com/api/v1/repos/saivardhan4694/coustomer_churn_prediction_system "HTTP/1.1 200 OK"]
[2024-12-13 23:21:57,831: INFO: _client: HTTP Request: GET https://dagshub.com/api/v1/user "HTTP/1.1 200 OK"]
[2024-12-13 23:21:57,831: INFO: helpers: Initialized MLflow to track repo "saivardhan4694/coustomer_churn_prediction_system"]
[2024-12-13 23:21:57,831: INFO: helpers: Repository saivardhan4694/coustomer_churn_prediction_system initialized!]
[2024-12-13 23:22:03,945: INFO: model_training: model Churn_KNN_Model loaded succesfully.]
[2024-12-13 23:22:03,945: INFO: model_training: initiating Churn_KNN_Model training]
[2024-12-13 23:22:22,101: INFO: model_training: Churn_KNN_Model training completed. metrics and artifacts are loaded to MLflow experiment KNN_Experiment]
[2024-12-13 23:22:33,269: INFO: model_training: model churn_logistic_reg_model loaded succesfully.]
[2024-12-13 23:22:33,269: INFO: model_training: initiating churn_logistic_reg_model training]
[2024-12-13 23:22:54,108: INFO: model_training: churn_logistic_reg_model training completed. metrics and artifacts are loaded to MLflow experiment Logistic_Regression_Experiment]
[2024-12-13 23:22:54,109: INFO: model_training_pipeline: model training completed successfully]
[2024-12-13 23:22:54,110: INFO: training_main: >>>>>>> stage Model training Stage completed <<<<<<<<

=================x]
[2024-12-13 23:25:12,969: INFO: training_main: >>>>>>> stage Model training Stage started <<<<<<<<]
[2024-12-13 23:25:12,975: INFO: common: yaml file: D:\repositories\coustomer_churn_prediction_system\config\training_config.yaml loaded successfully]
[2024-12-13 23:25:12,982: INFO: common: Directory Training_artifacts created successfully]
[2024-12-13 23:25:13,537: INFO: _client: HTTP Request: GET https://dagshub.com/api/v1/user "HTTP/1.1 200 OK"]
[2024-12-13 23:25:13,540: INFO: helpers: Accessing as saivardhan4694]
[2024-12-13 23:25:14,132: INFO: _client: HTTP Request: GET https://dagshub.com/api/v1/repos/saivardhan4694/coustomer_churn_prediction_system "HTTP/1.1 200 OK"]
[2024-12-13 23:25:14,666: INFO: _client: HTTP Request: GET https://dagshub.com/api/v1/user "HTTP/1.1 200 OK"]
[2024-12-13 23:25:14,668: INFO: helpers: Initialized MLflow to track repo "saivardhan4694/coustomer_churn_prediction_system"]
[2024-12-13 23:25:14,670: INFO: helpers: Repository saivardhan4694/coustomer_churn_prediction_system initialized!]
[2024-12-13 23:26:43,738: ERROR: model_training: Error in getting latest version of model: API request to https://dagshub.com/saivardhan4694/coustomer_churn_prediction_system.mlflow/api/2.0/mlflow/model-versions/get-download-uri failed with exception HTTPSConnectionPool(host='dagshub.com', port=443): Max retries exceeded with url: /saivardhan4694/coustomer_churn_prediction_system.mlflow/api/2.0/mlflow/model-versions/get-download-uri?name=Churn_KNN_Model&version=2 (Caused by ResponseError('too many 500 error responses'))]
[2024-12-13 23:26:43,740: ERROR: model_training_pipeline: Error in initiating model training pipeline: cannot unpack non-iterable NoneType object]
[2024-12-13 23:26:43,740: ERROR: training_main: cannot unpack non-iterable NoneType object]
Traceback (most recent call last):
  File "D:\repositories\coustomer_churn_prediction_system\training_main.py", line 40, in <module>
    model_trianing_pipeline.initiate_model_training()
  File "D:\repositories\coustomer_churn_prediction_system\src\churn_train\pipeline\model_training_pipeline.py", line 15, in initiate_model_training
    model_trainer.train_models()
  File "D:\repositories\coustomer_churn_prediction_system\src\churn_train\components\model_training.py", line 179, in train_models
    self.model_trainer(model_name=str(model),
  File "D:\repositories\coustomer_churn_prediction_system\src\churn_train\components\model_training.py", line 72, in model_trainer
    model_uri, model = self.load_latest_version_of_model(model_name= model_name)
TypeError: cannot unpack non-iterable NoneType object
[2024-12-13 23:28:48,218: INFO: training_main: >>>>>>> stage Model training Stage started <<<<<<<<]
[2024-12-13 23:28:48,233: INFO: common: yaml file: D:\repositories\coustomer_churn_prediction_system\config\training_config.yaml loaded successfully]
[2024-12-13 23:28:48,234: INFO: common: Directory Training_artifacts created successfully]
[2024-12-13 23:28:48,806: INFO: _client: HTTP Request: GET https://dagshub.com/api/v1/user "HTTP/1.1 200 OK"]
[2024-12-13 23:28:48,811: INFO: helpers: Accessing as saivardhan4694]
[2024-12-13 23:28:49,356: INFO: _client: HTTP Request: GET https://dagshub.com/api/v1/repos/saivardhan4694/coustomer_churn_prediction_system "HTTP/1.1 200 OK"]
[2024-12-13 23:28:49,875: INFO: _client: HTTP Request: GET https://dagshub.com/api/v1/user "HTTP/1.1 200 OK"]
[2024-12-13 23:28:49,877: INFO: helpers: Initialized MLflow to track repo "saivardhan4694/coustomer_churn_prediction_system"]
[2024-12-13 23:28:49,877: INFO: helpers: Repository saivardhan4694/coustomer_churn_prediction_system initialized!]
[2024-12-14 10:21:42,774: INFO: training_main: >>>>>>> stage Model training Stage started <<<<<<<<]
[2024-12-14 10:21:42,790: INFO: common: yaml file: D:\repositories\coustomer_churn_prediction_system\config\training_config.yaml loaded successfully]
[2024-12-14 10:21:42,790: INFO: common: Directory Training_artifacts created successfully]
[2024-12-14 10:21:43,678: INFO: _client: HTTP Request: GET https://dagshub.com/api/v1/user "HTTP/1.1 200 OK"]
[2024-12-14 10:21:43,679: INFO: helpers: Accessing as saivardhan4694]
[2024-12-14 10:21:44,233: INFO: _client: HTTP Request: GET https://dagshub.com/api/v1/repos/saivardhan4694/coustomer_churn_prediction_system "HTTP/1.1 200 OK"]
[2024-12-14 10:21:44,763: INFO: _client: HTTP Request: GET https://dagshub.com/api/v1/user "HTTP/1.1 200 OK"]
[2024-12-14 10:21:44,763: INFO: helpers: Initialized MLflow to track repo "saivardhan4694/coustomer_churn_prediction_system"]
[2024-12-14 10:21:44,763: INFO: helpers: Repository saivardhan4694/coustomer_churn_prediction_system initialized!]
[2024-12-14 10:22:56,102: ERROR: model_training: Error in getting latest version of model: API request to https://dagshub.com/saivardhan4694/coustomer_churn_prediction_system.mlflow/api/2.0/mlflow/model-versions/get-download-uri failed with exception HTTPSConnectionPool(host='dagshub.com', port=443): Max retries exceeded with url: /saivardhan4694/coustomer_churn_prediction_system.mlflow/api/2.0/mlflow/model-versions/get-download-uri?name=Churn_KNN_Model&version=2 (Caused by ResponseError('too many 500 error responses'))]
[2024-12-14 10:22:56,102: ERROR: model_training_pipeline: Error in initiating model training pipeline: cannot unpack non-iterable NoneType object]
[2024-12-14 10:22:56,102: ERROR: training_main: cannot unpack non-iterable NoneType object]
Traceback (most recent call last):
  File "D:\repositories\coustomer_churn_prediction_system\training_main.py", line 40, in <module>
    model_trianing_pipeline.initiate_model_training()
  File "D:\repositories\coustomer_churn_prediction_system\src\churn_train\pipeline\model_training_pipeline.py", line 15, in initiate_model_training
    model_trainer.train_models()
  File "D:\repositories\coustomer_churn_prediction_system\src\churn_train\components\model_training.py", line 179, in train_models
    self.model_trainer(model_name=str(model),
  File "D:\repositories\coustomer_churn_prediction_system\src\churn_train\components\model_training.py", line 72, in model_trainer
    model_uri, model = self.load_latest_version_of_model(model_name= model_name)
TypeError: cannot unpack non-iterable NoneType object
[2024-12-14 10:34:44,076: INFO: training_main: >>>>>>> stage Model training Stage started <<<<<<<<]
[2024-12-14 10:34:44,092: INFO: common: yaml file: D:\repositories\coustomer_churn_prediction_system\config\training_config.yaml loaded successfully]
[2024-12-14 10:34:44,093: INFO: common: Directory Training_artifacts created successfully]
[2024-12-14 10:34:44,701: INFO: _client: HTTP Request: GET https://dagshub.com/api/v1/user "HTTP/1.1 200 OK"]
[2024-12-14 10:34:44,708: INFO: helpers: Accessing as saivardhan4694]
[2024-12-14 10:34:45,268: INFO: _client: HTTP Request: GET https://dagshub.com/api/v1/repos/saivardhan4694/coustomer_churn_prediction_system "HTTP/1.1 200 OK"]
[2024-12-14 10:34:45,905: INFO: _client: HTTP Request: GET https://dagshub.com/api/v1/user "HTTP/1.1 200 OK"]
[2024-12-14 10:34:45,910: INFO: helpers: Initialized MLflow to track repo "saivardhan4694/coustomer_churn_prediction_system"]
[2024-12-14 10:34:45,911: INFO: helpers: Repository saivardhan4694/coustomer_churn_prediction_system initialized!]
[2024-12-14 10:34:59,448: INFO: model_training: model churn_random_forest_model loaded succesfully.]
[2024-12-14 10:34:59,448: INFO: model_training: initiating churn_random_forest_model training]
[2024-12-14 10:35:24,978: INFO: model_training: churn_random_forest_model training completed. metrics and artifacts are loaded to MLflow experiment Random_Forest_Experiment]
[2024-12-14 10:35:24,986: INFO: model_training_pipeline: model training completed successfully]
[2024-12-14 10:35:24,986: INFO: training_main: >>>>>>> stage Model training Stage completed <<<<<<<<

=================x]
[2024-12-14 10:35:52,070: INFO: training_main: >>>>>>> stage Model training Stage started <<<<<<<<]
[2024-12-14 10:35:52,073: INFO: common: yaml file: D:\repositories\coustomer_churn_prediction_system\config\training_config.yaml loaded successfully]
[2024-12-14 10:35:52,073: INFO: common: Directory Training_artifacts created successfully]
[2024-12-14 10:35:52,650: INFO: _client: HTTP Request: GET https://dagshub.com/api/v1/user "HTTP/1.1 200 OK"]
[2024-12-14 10:35:52,650: INFO: helpers: Accessing as saivardhan4694]
[2024-12-14 10:35:53,294: INFO: _client: HTTP Request: GET https://dagshub.com/api/v1/repos/saivardhan4694/coustomer_churn_prediction_system "HTTP/1.1 200 OK"]
[2024-12-14 10:35:53,829: INFO: _client: HTTP Request: GET https://dagshub.com/api/v1/user "HTTP/1.1 200 OK"]
[2024-12-14 10:35:53,831: INFO: helpers: Initialized MLflow to track repo "saivardhan4694/coustomer_churn_prediction_system"]
[2024-12-14 10:35:53,833: INFO: helpers: Repository saivardhan4694/coustomer_churn_prediction_system initialized!]
[2024-12-14 10:36:00,117: INFO: model_training: model churn_random_forest_model loaded succesfully.]
[2024-12-14 10:36:00,117: INFO: model_training: initiating churn_random_forest_model training]
[2024-12-14 10:36:23,506: INFO: model_training: churn_random_forest_model training completed. metrics and artifacts are loaded to MLflow experiment Random_Forest_Experiment]
[2024-12-14 10:36:23,508: INFO: model_training_pipeline: model training completed successfully]
[2024-12-14 10:36:23,508: INFO: training_main: >>>>>>> stage Model training Stage completed <<<<<<<<

=================x]
[2024-12-14 10:36:48,314: INFO: training_main: >>>>>>> stage Model training Stage started <<<<<<<<]
[2024-12-14 10:36:48,331: INFO: common: yaml file: D:\repositories\coustomer_churn_prediction_system\config\training_config.yaml loaded successfully]
[2024-12-14 10:36:48,331: INFO: common: Directory Training_artifacts created successfully]
[2024-12-14 10:36:48,911: INFO: _client: HTTP Request: GET https://dagshub.com/api/v1/user "HTTP/1.1 200 OK"]
[2024-12-14 10:36:48,914: INFO: helpers: Accessing as saivardhan4694]
[2024-12-14 10:36:49,498: INFO: _client: HTTP Request: GET https://dagshub.com/api/v1/repos/saivardhan4694/coustomer_churn_prediction_system "HTTP/1.1 200 OK"]
[2024-12-14 10:36:50,138: INFO: _client: HTTP Request: GET https://dagshub.com/api/v1/user "HTTP/1.1 200 OK"]
[2024-12-14 10:36:50,141: INFO: helpers: Initialized MLflow to track repo "saivardhan4694/coustomer_churn_prediction_system"]
[2024-12-14 10:36:50,142: INFO: helpers: Repository saivardhan4694/coustomer_churn_prediction_system initialized!]
[2024-12-14 10:38:46,031: INFO: training_main: >>>>>>> stage Model training Stage started <<<<<<<<]
[2024-12-14 10:38:46,047: INFO: common: yaml file: D:\repositories\coustomer_churn_prediction_system\config\training_config.yaml loaded successfully]
[2024-12-14 10:38:46,047: INFO: common: Directory Training_artifacts created successfully]
[2024-12-14 10:38:46,669: INFO: _client: HTTP Request: GET https://dagshub.com/api/v1/user "HTTP/1.1 200 OK"]
[2024-12-14 10:38:46,683: INFO: helpers: Accessing as saivardhan4694]
[2024-12-14 10:38:47,214: INFO: _client: HTTP Request: GET https://dagshub.com/api/v1/repos/saivardhan4694/coustomer_churn_prediction_system "HTTP/1.1 200 OK"]
[2024-12-14 10:38:47,746: INFO: _client: HTTP Request: GET https://dagshub.com/api/v1/user "HTTP/1.1 200 OK"]
[2024-12-14 10:38:47,749: INFO: helpers: Initialized MLflow to track repo "saivardhan4694/coustomer_churn_prediction_system"]
[2024-12-14 10:38:47,749: INFO: helpers: Repository saivardhan4694/coustomer_churn_prediction_system initialized!]
[2024-12-14 10:38:53,354: INFO: model_training: model churn_random_forest_model loaded succesfully.]
[2024-12-14 10:38:53,354: INFO: model_training: initiating churn_random_forest_model training]
[2024-12-14 10:39:16,407: INFO: model_training: churn_random_forest_model training completed. metrics and artifacts are loaded to MLflow experiment Random_Forest_Experiment]
[2024-12-14 10:39:16,410: INFO: model_training_pipeline: model training completed successfully]
[2024-12-14 10:39:16,410: INFO: training_main: >>>>>>> stage Model training Stage completed <<<<<<<<

=================x]
[2024-12-14 10:41:45,185: INFO: training_main: >>>>>>> stage Model training Stage started <<<<<<<<]
[2024-12-14 10:41:45,203: INFO: common: yaml file: D:\repositories\coustomer_churn_prediction_system\config\training_config.yaml loaded successfully]
[2024-12-14 10:41:45,203: INFO: common: Directory Training_artifacts created successfully]
[2024-12-14 10:41:45,762: INFO: _client: HTTP Request: GET https://dagshub.com/api/v1/user "HTTP/1.1 200 OK"]
[2024-12-14 10:41:45,764: INFO: helpers: Accessing as saivardhan4694]
[2024-12-14 10:41:46,380: INFO: _client: HTTP Request: GET https://dagshub.com/api/v1/repos/saivardhan4694/coustomer_churn_prediction_system "HTTP/1.1 200 OK"]
[2024-12-14 10:41:46,900: INFO: _client: HTTP Request: GET https://dagshub.com/api/v1/user "HTTP/1.1 200 OK"]
[2024-12-14 10:41:46,900: INFO: helpers: Initialized MLflow to track repo "saivardhan4694/coustomer_churn_prediction_system"]
[2024-12-14 10:41:46,900: INFO: helpers: Repository saivardhan4694/coustomer_churn_prediction_system initialized!]
[2024-12-14 10:41:51,987: INFO: model_training: model churn_svm_model loaded succesfully.]
[2024-12-14 10:41:51,987: INFO: model_training: initiating churn_svm_model training]
[2024-12-14 10:42:13,712: INFO: model_training: churn_svm_model training completed. metrics and artifacts are loaded to MLflow experiment SVM_Experiment]
[2024-12-14 10:42:13,718: INFO: model_training_pipeline: model training completed successfully]
[2024-12-14 10:42:13,718: INFO: training_main: >>>>>>> stage Model training Stage completed <<<<<<<<

=================x]
[2024-12-14 11:01:10,978: INFO: training_main: >>>>>>> stage Model training Stage started <<<<<<<<]
[2024-12-14 11:01:10,988: INFO: common: yaml file: D:\repositories\coustomer_churn_prediction_system\config\training_config.yaml loaded successfully]
[2024-12-14 11:01:10,988: INFO: common: Directory Training_artifacts created successfully]
[2024-12-14 11:01:11,567: INFO: _client: HTTP Request: GET https://dagshub.com/api/v1/user "HTTP/1.1 200 OK"]
[2024-12-14 11:01:11,573: INFO: helpers: Accessing as saivardhan4694]
[2024-12-14 11:01:12,127: INFO: _client: HTTP Request: GET https://dagshub.com/api/v1/repos/saivardhan4694/coustomer_churn_prediction_system "HTTP/1.1 200 OK"]
[2024-12-14 11:01:12,710: INFO: _client: HTTP Request: GET https://dagshub.com/api/v1/user "HTTP/1.1 200 OK"]
[2024-12-14 11:01:12,712: INFO: helpers: Initialized MLflow to track repo "saivardhan4694/coustomer_churn_prediction_system"]
[2024-12-14 11:01:12,712: INFO: helpers: Repository saivardhan4694/coustomer_churn_prediction_system initialized!]
[2024-12-14 11:01:21,224: ERROR: model_training: Error in getting latest version of model: No module named 'xgboost']
[2024-12-14 11:01:21,225: ERROR: model_training_pipeline: Error in initiating model training pipeline: cannot unpack non-iterable NoneType object]
[2024-12-14 11:01:21,225: ERROR: training_main: cannot unpack non-iterable NoneType object]
Traceback (most recent call last):
  File "D:\repositories\coustomer_churn_prediction_system\training_main.py", line 40, in <module>
    model_trianing_pipeline.initiate_model_training()
  File "D:\repositories\coustomer_churn_prediction_system\src\churn_train\pipeline\model_training_pipeline.py", line 15, in initiate_model_training
    model_trainer.train_models()
  File "D:\repositories\coustomer_churn_prediction_system\src\churn_train\components\model_training.py", line 190, in train_models
    self.model_trainer(model_name=str(model),
  File "D:\repositories\coustomer_churn_prediction_system\src\churn_train\components\model_training.py", line 72, in model_trainer
    model_uri, model = self.load_latest_version_of_model(model_name= model_name)
TypeError: cannot unpack non-iterable NoneType object
[2024-12-14 11:01:38,906: INFO: training_main: >>>>>>> stage Model training Stage started <<<<<<<<]
[2024-12-14 11:01:38,908: INFO: common: yaml file: D:\repositories\coustomer_churn_prediction_system\config\training_config.yaml loaded successfully]
[2024-12-14 11:01:38,908: INFO: common: Directory Training_artifacts created successfully]
[2024-12-14 11:01:39,490: INFO: _client: HTTP Request: GET https://dagshub.com/api/v1/user "HTTP/1.1 200 OK"]
[2024-12-14 11:01:39,490: INFO: helpers: Accessing as saivardhan4694]
[2024-12-14 11:01:40,050: INFO: _client: HTTP Request: GET https://dagshub.com/api/v1/repos/saivardhan4694/coustomer_churn_prediction_system "HTTP/1.1 200 OK"]
[2024-12-14 11:01:40,659: INFO: _client: HTTP Request: GET https://dagshub.com/api/v1/user "HTTP/1.1 200 OK"]
[2024-12-14 11:01:40,662: INFO: helpers: Initialized MLflow to track repo "saivardhan4694/coustomer_churn_prediction_system"]
[2024-12-14 11:01:40,662: INFO: helpers: Repository saivardhan4694/coustomer_churn_prediction_system initialized!]
[2024-12-14 11:03:56,842: INFO: training_main: >>>>>>> stage Model training Stage started <<<<<<<<]
[2024-12-14 11:03:56,858: INFO: common: yaml file: D:\repositories\coustomer_churn_prediction_system\config\training_config.yaml loaded successfully]
[2024-12-14 11:03:56,858: INFO: common: Directory Training_artifacts created successfully]
[2024-12-14 11:03:57,473: INFO: _client: HTTP Request: GET https://dagshub.com/api/v1/user "HTTP/1.1 200 OK"]
[2024-12-14 11:03:57,475: INFO: helpers: Accessing as saivardhan4694]
[2024-12-14 11:03:58,067: INFO: _client: HTTP Request: GET https://dagshub.com/api/v1/repos/saivardhan4694/coustomer_churn_prediction_system "HTTP/1.1 200 OK"]
[2024-12-14 11:03:58,597: INFO: _client: HTTP Request: GET https://dagshub.com/api/v1/user "HTTP/1.1 200 OK"]
[2024-12-14 11:03:58,598: INFO: helpers: Initialized MLflow to track repo "saivardhan4694/coustomer_churn_prediction_system"]
[2024-12-14 11:03:58,598: INFO: helpers: Repository saivardhan4694/coustomer_churn_prediction_system initialized!]
[2024-12-14 11:04:04,999: INFO: model_training: model Churn_KNN_Model loaded succesfully.]
[2024-12-14 11:04:04,999: INFO: model_training: initiating Churn_KNN_Model training]
[2024-12-14 11:04:32,948: INFO: model_training: Churn_KNN_Model training completed. metrics and artifacts are loaded to MLflow experiment KNN_Experiment]
[2024-12-14 11:04:43,766: INFO: model_training: model churn_logistic_reg_model loaded succesfully.]
[2024-12-14 11:04:43,768: INFO: model_training: initiating churn_logistic_reg_model training]
[2024-12-14 11:05:13,585: INFO: model_training: churn_logistic_reg_model training completed. metrics and artifacts are loaded to MLflow experiment Logistic_Regression_Experiment]
[2024-12-14 11:05:24,738: INFO: model_training: model churn_random_forest_model loaded succesfully.]
[2024-12-14 11:05:24,738: INFO: model_training: initiating churn_random_forest_model training]
[2024-12-14 11:06:05,386: INFO: model_training: churn_random_forest_model training completed. metrics and artifacts are loaded to MLflow experiment Random_Forest_Experiment]
[2024-12-14 11:06:10,809: INFO: model_training: model churn_svm_model loaded succesfully.]
[2024-12-14 11:06:10,813: INFO: model_training: initiating churn_svm_model training]
[2024-12-14 11:06:41,162: INFO: model_training: churn_svm_model training completed. metrics and artifacts are loaded to MLflow experiment SVM_Experiment]
[2024-12-14 11:06:52,345: ERROR: model_training: Error in getting latest version of model: No module named 'xgboost']
[2024-12-14 11:06:52,347: ERROR: model_training_pipeline: Error in initiating model training pipeline: cannot unpack non-iterable NoneType object]
[2024-12-14 11:06:52,347: ERROR: training_main: cannot unpack non-iterable NoneType object]
Traceback (most recent call last):
  File "D:\repositories\coustomer_churn_prediction_system\training_main.py", line 40, in <module>
    model_trianing_pipeline.initiate_model_training()
  File "D:\repositories\coustomer_churn_prediction_system\src\churn_train\pipeline\model_training_pipeline.py", line 15, in initiate_model_training
    model_trainer.train_models()
  File "D:\repositories\coustomer_churn_prediction_system\src\churn_train\components\model_training.py", line 190, in train_models
    self.set_auto_register_model()
  File "D:\repositories\coustomer_churn_prediction_system\src\churn_train\components\model_training.py", line 72, in model_trainer
    def model_trainer(self, model_name, experiment_name,
TypeError: cannot unpack non-iterable NoneType object
[2024-12-14 11:09:32,824: INFO: training_main: >>>>>>> stage Model training Stage started <<<<<<<<]
[2024-12-14 11:09:32,838: INFO: common: yaml file: D:\repositories\coustomer_churn_prediction_system\config\training_config.yaml loaded successfully]
[2024-12-14 11:09:32,838: INFO: common: Directory Training_artifacts created successfully]
[2024-12-14 11:09:33,412: INFO: _client: HTTP Request: GET https://dagshub.com/api/v1/user "HTTP/1.1 200 OK"]
[2024-12-14 11:09:33,415: INFO: helpers: Accessing as saivardhan4694]
[2024-12-14 11:09:33,979: INFO: _client: HTTP Request: GET https://dagshub.com/api/v1/repos/saivardhan4694/coustomer_churn_prediction_system "HTTP/1.1 200 OK"]
[2024-12-14 11:09:34,566: INFO: _client: HTTP Request: GET https://dagshub.com/api/v1/user "HTTP/1.1 200 OK"]
[2024-12-14 11:09:34,575: INFO: helpers: Initialized MLflow to track repo "saivardhan4694/coustomer_churn_prediction_system"]
[2024-12-14 11:09:34,576: INFO: helpers: Repository saivardhan4694/coustomer_churn_prediction_system initialized!]
[2024-12-14 11:09:48,728: INFO: model_training: model churn_logistic_reg_model loaded succesfully.]
[2024-12-14 11:09:48,728: INFO: model_training: initiating churn_logistic_reg_model training]
[2024-12-14 11:10:15,020: INFO: model_training: churn_logistic_reg_model training completed. metrics and artifacts are loaded to MLflow experiment Logistic_Regression_Experiment]
[2024-12-14 11:10:15,021: INFO: model_training_pipeline: model training completed successfully]
[2024-12-14 11:10:15,021: INFO: training_main: >>>>>>> stage Model training Stage completed <<<<<<<<

=================x]
[2024-12-14 12:18:23,636: INFO: etl_main: >>>>>>> stage extract started <<<<<<<<]
[2024-12-14 12:18:23,636: INFO: common: yaml file: D:\repositories\coustomer_churn_prediction_system\config\etl_config.yaml loaded successfully]
[2024-12-14 12:18:23,636: INFO: common: Directory ETL_artifacts created successfully]
[2024-12-14 12:18:23,636: INFO: common: Directory ETL_artifacts/data_Extracting created successfully]
[2024-12-14 12:18:30,449: INFO: data_extracting: data succesfully fetched from customer_churn_data and table customers]
[2024-12-14 12:18:30,449: INFO: etl_main: >>>>>>> stage extract completed <<<<<<<<

=================x]
[2024-12-14 12:20:20,437: INFO: etl_main: >>>>>>> stage extract started <<<<<<<<]
[2024-12-14 12:20:20,450: INFO: common: yaml file: D:\repositories\coustomer_churn_prediction_system\config\etl_config.yaml loaded successfully]
[2024-12-14 12:20:20,450: INFO: common: Directory ETL_artifacts created successfully]
[2024-12-14 12:20:20,450: INFO: common: Directory ETL_artifacts/data_Extracting created successfully]
[2024-12-14 12:20:26,783: INFO: data_extracting: data succesfully fetched from customer_churn_data and table customers]
[2024-12-14 12:20:26,783: INFO: etl_main: >>>>>>> stage extract completed <<<<<<<<

=================x]
[2024-12-14 12:20:29,413: INFO: etl_main: >>>>>>> stage transform started <<<<<<<<]
[2024-12-14 12:20:29,431: INFO: common: yaml file: D:\repositories\coustomer_churn_prediction_system\config\etl_config.yaml loaded successfully]
[2024-12-14 12:20:29,431: INFO: common: Directory ETL_artifacts created successfully]
[2024-12-14 12:20:29,431: INFO: common: Directory ETL_artifacts/data_transformation created successfully]
[2024-12-14 12:20:29,454: INFO: data_transformation: Schema Validation Passed: Column names and data types match expectations.]
[2024-12-14 12:20:29,465: INFO: data_transformation: No duplicate rows found.]
[2024-12-14 12:21:19,809: INFO: data_transformation: misssing values handled succesfully.]
[2024-12-14 12:21:19,943: INFO: etl_main: >>>>>>> stage transform completed <<<<<<<<

=================x]
[2024-12-14 12:21:22,607: INFO: etl_main: >>>>>>> stage load started <<<<<<<<]
[2024-12-14 12:21:22,607: INFO: common: yaml file: D:\repositories\coustomer_churn_prediction_system\config\etl_config.yaml loaded successfully]
[2024-12-14 12:21:22,607: INFO: common: Directory ETL_artifacts created successfully]
[2024-12-14 12:21:22,620: INFO: common: Directory Data created successfully]
[2024-12-14 12:21:22,705: INFO: data_loader: data succesfully loaded to Data/data.csv]
[2024-12-14 12:21:22,707: INFO: etl_main: >>>>>>> stage load completed <<<<<<<<

=================x]
[2024-12-14 12:32:18,805: INFO: etl_main: >>>>>>> stage extract started <<<<<<<<]
[2024-12-14 12:32:18,814: INFO: common: yaml file: D:\repositories\coustomer_churn_prediction_system\config\etl_config.yaml loaded successfully]
[2024-12-14 12:32:18,814: INFO: common: Directory ETL_artifacts created successfully]
[2024-12-14 12:32:18,814: INFO: common: Directory ETL_artifacts/data_Extracting created successfully]
[2024-12-14 12:32:27,233: INFO: data_extracting: data succesfully fetched from customer_churn_data and table customers]
[2024-12-14 12:32:27,237: INFO: etl_main: >>>>>>> stage extract completed <<<<<<<<

=================x]
[2024-12-14 12:32:30,071: INFO: etl_main: >>>>>>> stage transform started <<<<<<<<]
[2024-12-14 12:32:30,071: INFO: common: yaml file: D:\repositories\coustomer_churn_prediction_system\config\etl_config.yaml loaded successfully]
[2024-12-14 12:32:30,071: INFO: common: Directory ETL_artifacts created successfully]
[2024-12-14 12:32:30,071: INFO: common: Directory ETL_artifacts/data_transformation created successfully]
[2024-12-14 12:32:30,136: INFO: data_transformation: Column 'Churn' has incorrect data type. Expected int64, got float64]
[2024-12-14 12:32:30,136: INFO: etl_main: >>>>>>> stage transform completed <<<<<<<<

=================x]
[2024-12-14 12:48:51,740: INFO: etl_main: >>>>>>> stage transform started <<<<<<<<]
[2024-12-14 12:48:51,756: INFO: common: yaml file: D:\repositories\coustomer_churn_prediction_system\config\etl_config.yaml loaded successfully]
[2024-12-14 12:48:51,756: INFO: common: Directory ETL_artifacts created successfully]
[2024-12-14 12:48:51,756: INFO: common: Directory ETL_artifacts/data_transformation created successfully]
[2024-12-14 12:48:51,806: INFO: data_transformation: Column 'Churn' has incorrect data type. Expected int64, got float64]
[2024-12-14 12:48:51,806: INFO: data_transformation: Column 'CityTier' has incorrect data type. Expected int64, got float64]
[2024-12-14 12:48:51,806: INFO: data_transformation: Column 'NumberOfDeviceRegistered' has incorrect data type. Expected int64, got float64]
[2024-12-14 12:48:51,814: INFO: data_transformation: Column 'SatisfactionScore' has incorrect data type. Expected int64, got float64]
[2024-12-14 12:48:51,814: INFO: data_transformation: Column 'NumberOfAddress' has incorrect data type. Expected int64, got float64]
[2024-12-14 12:48:51,814: INFO: data_transformation: Column 'Complain' has incorrect data type. Expected int64, got float64]
[2024-12-14 12:48:51,814: INFO: data_transformation: Schema Validation Passed: Column names and data types match expectations.]
[2024-12-14 12:48:51,816: INFO: etl_main: >>>>>>> stage transform completed <<<<<<<<

=================x]
[2024-12-14 12:59:27,634: INFO: etl_main: >>>>>>> stage transform started <<<<<<<<]
[2024-12-14 12:59:27,647: INFO: common: yaml file: D:\repositories\coustomer_churn_prediction_system\config\etl_config.yaml loaded successfully]
[2024-12-14 12:59:27,647: INFO: common: Directory ETL_artifacts created successfully]
[2024-12-14 12:59:27,647: INFO: common: Directory ETL_artifacts/data_transformation created successfully]
[2024-12-14 12:59:27,706: INFO: data_transformation: Schema Validation Passed: Column names and data types match expectations.]
[2024-12-14 12:59:27,723: INFO: data_transformation: Found 239 duplicate rows. Removing duplicates.]
[2024-12-14 13:02:41,853: INFO: data_transformation: misssing values handled succesfully.]
[2024-12-14 13:02:42,029: INFO: etl_main: >>>>>>> stage transform completed <<<<<<<<

=================x]
[2024-12-14 13:02:43,356: INFO: etl_main: >>>>>>> stage load started <<<<<<<<]
[2024-12-14 13:02:43,359: INFO: common: yaml file: D:\repositories\coustomer_churn_prediction_system\config\etl_config.yaml loaded successfully]
[2024-12-14 13:02:43,359: INFO: common: Directory ETL_artifacts created successfully]
[2024-12-14 13:02:43,359: INFO: common: Directory Data created successfully]
[2024-12-14 13:02:43,531: INFO: data_loader: data succesfully loaded to Data/data.csv]
[2024-12-14 13:02:43,531: INFO: etl_main: >>>>>>> stage load completed <<<<<<<<

=================x]
[2024-12-14 17:24:18,526: INFO: _client: HTTP Request: GET https://dagshub.com/api/v1/user "HTTP/1.1 200 OK"]
[2024-12-14 17:24:18,537: INFO: helpers: Accessing as saivardhan4694]
[2024-12-14 17:24:19,052: INFO: _client: HTTP Request: GET https://dagshub.com/api/v1/repos/saivardhan4694/coustomer_churn_prediction_system "HTTP/1.1 200 OK"]
[2024-12-14 17:24:19,535: INFO: _client: HTTP Request: GET https://dagshub.com/api/v1/user "HTTP/1.1 200 OK"]
[2024-12-14 17:24:19,535: INFO: helpers: Initialized MLflow to track repo "saivardhan4694/coustomer_churn_prediction_system"]
[2024-12-14 17:24:19,535: INFO: helpers: Repository saivardhan4694/coustomer_churn_prediction_system initialized!]
[2024-12-14 17:25:41,613: INFO: _client: HTTP Request: GET https://dagshub.com/api/v1/user "HTTP/1.1 200 OK"]
[2024-12-14 17:25:41,613: INFO: helpers: Accessing as saivardhan4694]
[2024-12-14 17:25:42,135: INFO: _client: HTTP Request: GET https://dagshub.com/api/v1/repos/saivardhan4694/coustomer_churn_prediction_system "HTTP/1.1 200 OK"]
[2024-12-14 17:25:42,598: INFO: _client: HTTP Request: GET https://dagshub.com/api/v1/user "HTTP/1.1 200 OK"]
[2024-12-14 17:25:42,614: INFO: helpers: Initialized MLflow to track repo "saivardhan4694/coustomer_churn_prediction_system"]
[2024-12-14 17:25:42,616: INFO: helpers: Repository saivardhan4694/coustomer_churn_prediction_system initialized!]
[2024-12-14 17:25:46,733: INFO: common: yaml file: D:\repositories\coustomer_churn_prediction_system\config\prediction_config.yaml loaded successfully]
[2024-12-14 17:25:46,735: INFO: common: Directory prediction_artifacts created successfully]
[2024-12-14 17:25:46,735: INFO: common: Directory prediction_artifacts/data_validation created successfully]
[2024-12-14 17:27:43,175: INFO: _client: HTTP Request: GET https://dagshub.com/api/v1/user "HTTP/1.1 200 OK"]
[2024-12-14 17:27:43,175: INFO: helpers: Accessing as saivardhan4694]
[2024-12-14 17:27:43,662: INFO: _client: HTTP Request: GET https://dagshub.com/api/v1/repos/saivardhan4694/coustomer_churn_prediction_system "HTTP/1.1 200 OK"]
[2024-12-14 17:27:44,145: INFO: _client: HTTP Request: GET https://dagshub.com/api/v1/user "HTTP/1.1 200 OK"]
[2024-12-14 17:27:44,147: INFO: helpers: Initialized MLflow to track repo "saivardhan4694/coustomer_churn_prediction_system"]
[2024-12-14 17:27:44,147: INFO: helpers: Repository saivardhan4694/coustomer_churn_prediction_system initialized!]
[2024-12-14 17:27:48,123: INFO: common: yaml file: D:\repositories\coustomer_churn_prediction_system\config\prediction_config.yaml loaded successfully]
[2024-12-14 17:27:48,125: INFO: common: Directory prediction_artifacts created successfully]
[2024-12-14 17:27:48,125: INFO: common: Directory prediction_artifacts/data_validation created successfully]
[2024-12-14 17:28:32,948: INFO: _client: HTTP Request: GET https://dagshub.com/api/v1/user "HTTP/1.1 200 OK"]
[2024-12-14 17:28:32,952: INFO: helpers: Accessing as saivardhan4694]
[2024-12-14 17:28:33,475: INFO: _client: HTTP Request: GET https://dagshub.com/api/v1/repos/saivardhan4694/coustomer_churn_prediction_system "HTTP/1.1 200 OK"]
[2024-12-14 17:28:33,961: INFO: _client: HTTP Request: GET https://dagshub.com/api/v1/user "HTTP/1.1 200 OK"]
[2024-12-14 17:28:33,968: INFO: helpers: Initialized MLflow to track repo "saivardhan4694/coustomer_churn_prediction_system"]
[2024-12-14 17:28:33,968: INFO: helpers: Repository saivardhan4694/coustomer_churn_prediction_system initialized!]
[2024-12-14 17:28:40,759: INFO: common: yaml file: D:\repositories\coustomer_churn_prediction_system\config\prediction_config.yaml loaded successfully]
[2024-12-14 17:28:40,759: INFO: common: Directory prediction_artifacts created successfully]
[2024-12-14 17:28:40,759: INFO: common: Directory prediction_artifacts/data_validation created successfully]
[2024-12-14 17:28:40,759: WARNING: validator: Extra columns: {'Churn'}]
[2024-12-14 17:28:40,765: ERROR: validator: Column 'CityTier' contains invalid values: [1.65427679]]
[2024-12-14 17:28:40,769: ERROR: validator: Column 'Complain' contains invalid values: [0.24557982]]
[2024-12-14 17:28:40,770: ERROR: validator: Schema Validation Failed. See errors for details.]
[2024-12-14 17:32:10,051: INFO: _client: HTTP Request: GET https://dagshub.com/api/v1/user "HTTP/1.1 200 OK"]
[2024-12-14 17:32:10,052: INFO: helpers: Accessing as saivardhan4694]
[2024-12-14 17:32:10,559: INFO: _client: HTTP Request: GET https://dagshub.com/api/v1/repos/saivardhan4694/coustomer_churn_prediction_system "HTTP/1.1 200 OK"]
[2024-12-14 17:32:11,055: INFO: _client: HTTP Request: GET https://dagshub.com/api/v1/user "HTTP/1.1 200 OK"]
[2024-12-14 17:32:11,061: INFO: helpers: Initialized MLflow to track repo "saivardhan4694/coustomer_churn_prediction_system"]
[2024-12-14 17:32:11,061: INFO: helpers: Repository saivardhan4694/coustomer_churn_prediction_system initialized!]
[2024-12-14 17:32:15,736: INFO: common: yaml file: D:\repositories\coustomer_churn_prediction_system\config\prediction_config.yaml loaded successfully]
[2024-12-14 17:32:15,737: INFO: common: Directory prediction_artifacts created successfully]
[2024-12-14 17:32:15,737: INFO: common: Directory prediction_artifacts/data_validation created successfully]
[2024-12-14 17:32:15,738: ERROR: validator: Column 'CustomerID' has incorrect data type. Expected float64, got int64]
[2024-12-14 17:32:15,738: ERROR: validator: Column 'CityTier' has incorrect data type. Expected float64, got int64]
[2024-12-14 17:32:15,738: ERROR: validator: Column 'SatisfactionScore' has incorrect data type. Expected float64, got int64]
[2024-12-14 17:32:15,738: ERROR: validator: Column 'NumberOfAddress' has incorrect data type. Expected float64, got int64]
[2024-12-14 17:32:15,738: ERROR: validator: Column 'Complain' has incorrect data type. Expected float64, got int64]
[2024-12-14 17:32:15,738: ERROR: validator: Column 'CouponUsed' has incorrect data type. Expected float64, got int64]
[2024-12-14 17:32:15,738: ERROR: validator: Column 'OrderCount' has incorrect data type. Expected float64, got int64]
[2024-12-14 17:32:15,738: ERROR: validator: Column 'DaySinceLastOrder' has incorrect data type. Expected float64, got int64]
[2024-12-14 17:32:15,742: ERROR: validator: Schema Validation Failed. See errors for details.]
[2024-12-14 17:40:59,549: INFO: _client: HTTP Request: GET https://dagshub.com/api/v1/user "HTTP/1.1 200 OK"]
[2024-12-14 17:40:59,549: INFO: helpers: Accessing as saivardhan4694]
[2024-12-14 17:41:00,067: INFO: _client: HTTP Request: GET https://dagshub.com/api/v1/repos/saivardhan4694/coustomer_churn_prediction_system "HTTP/1.1 200 OK"]
[2024-12-14 17:41:00,567: INFO: _client: HTTP Request: GET https://dagshub.com/api/v1/user "HTTP/1.1 200 OK"]
[2024-12-14 17:41:00,567: INFO: helpers: Initialized MLflow to track repo "saivardhan4694/coustomer_churn_prediction_system"]
[2024-12-14 17:41:00,567: INFO: helpers: Repository saivardhan4694/coustomer_churn_prediction_system initialized!]
[2024-12-14 17:41:05,841: INFO: common: yaml file: D:\repositories\coustomer_churn_prediction_system\config\prediction_config.yaml loaded successfully]
[2024-12-14 17:41:05,842: INFO: common: Directory prediction_artifacts created successfully]
[2024-12-14 17:41:05,842: INFO: common: Directory prediction_artifacts/data_validation created successfully]
[2024-12-14 17:41:05,846: INFO: validator: Schema Validation Passed: Column names, data types, and constraints match expectations.]
[2024-12-14 17:43:10,867: INFO: _client: HTTP Request: GET https://dagshub.com/api/v1/user "HTTP/1.1 200 OK"]
[2024-12-14 17:43:10,872: INFO: helpers: Accessing as saivardhan4694]
[2024-12-14 17:43:11,438: INFO: _client: HTTP Request: GET https://dagshub.com/api/v1/repos/saivardhan4694/coustomer_churn_prediction_system "HTTP/1.1 200 OK"]
[2024-12-14 17:43:11,916: INFO: _client: HTTP Request: GET https://dagshub.com/api/v1/user "HTTP/1.1 200 OK"]
[2024-12-14 17:43:11,916: INFO: helpers: Initialized MLflow to track repo "saivardhan4694/coustomer_churn_prediction_system"]
[2024-12-14 17:43:11,916: INFO: helpers: Repository saivardhan4694/coustomer_churn_prediction_system initialized!]
[2024-12-14 17:43:17,721: INFO: common: yaml file: D:\repositories\coustomer_churn_prediction_system\config\prediction_config.yaml loaded successfully]
[2024-12-14 17:43:17,723: INFO: common: Directory prediction_artifacts created successfully]
[2024-12-14 17:43:17,724: INFO: common: Directory prediction_artifacts/data_validation created successfully]
[2024-12-14 17:43:17,728: INFO: validator: Schema Validation Passed: Column names, data types, and constraints match expectations.]
[2024-12-14 17:47:10,280: INFO: _client: HTTP Request: GET https://dagshub.com/api/v1/user "HTTP/1.1 200 OK"]
[2024-12-14 17:47:10,288: INFO: helpers: Accessing as saivardhan4694]
[2024-12-14 17:47:10,814: INFO: _client: HTTP Request: GET https://dagshub.com/api/v1/repos/saivardhan4694/coustomer_churn_prediction_system "HTTP/1.1 200 OK"]
[2024-12-14 17:47:11,275: INFO: _client: HTTP Request: GET https://dagshub.com/api/v1/user "HTTP/1.1 200 OK"]
[2024-12-14 17:47:11,291: INFO: helpers: Initialized MLflow to track repo "saivardhan4694/coustomer_churn_prediction_system"]
[2024-12-14 17:47:11,291: INFO: helpers: Repository saivardhan4694/coustomer_churn_prediction_system initialized!]
[2024-12-14 17:47:16,020: INFO: common: yaml file: D:\repositories\coustomer_churn_prediction_system\config\prediction_config.yaml loaded successfully]
[2024-12-14 17:47:16,020: INFO: common: Directory prediction_artifacts created successfully]
[2024-12-14 17:47:16,022: INFO: common: Directory prediction_artifacts/data_validation created successfully]
[2024-12-14 17:47:16,024: INFO: validator: Schema Validation Passed: Column names, data types, and constraints match expectations.]
[2024-12-14 18:03:10,433: INFO: common: yaml file: D:\repositories\coustomer_churn_prediction_system\config\prediction_config.yaml loaded successfully]
[2024-12-14 18:03:10,435: INFO: common: Directory prediction_artifacts created successfully]
[2024-12-14 18:03:11,285: INFO: _client: HTTP Request: GET https://dagshub.com/api/v1/user "HTTP/1.1 200 OK"]
[2024-12-14 18:03:11,288: INFO: helpers: Accessing as saivardhan4694]
[2024-12-14 18:03:11,834: INFO: _client: HTTP Request: GET https://dagshub.com/api/v1/repos/saivardhan4694/coustomer_churn_prediction_system "HTTP/1.1 200 OK"]
[2024-12-14 18:03:12,307: INFO: _client: HTTP Request: GET https://dagshub.com/api/v1/user "HTTP/1.1 200 OK"]
[2024-12-14 18:03:12,307: INFO: helpers: Initialized MLflow to track repo "saivardhan4694/coustomer_churn_prediction_system"]
[2024-12-14 18:03:12,307: INFO: helpers: Repository saivardhan4694/coustomer_churn_prediction_system initialized!]
[2024-12-14 18:03:16,484: INFO: common: Directory prediction_artifacts/data_validation created successfully]
[2024-12-14 18:03:16,488: INFO: validator: Schema Validation Passed: Column names, data types, and constraints match expectations.]
[2024-12-14 18:04:29,248: INFO: common: yaml file: D:\repositories\coustomer_churn_prediction_system\config\prediction_config.yaml loaded successfully]
[2024-12-14 18:04:29,248: INFO: common: Directory prediction_artifacts created successfully]
[2024-12-14 18:04:29,775: INFO: _client: HTTP Request: GET https://dagshub.com/api/v1/user "HTTP/1.1 200 OK"]
[2024-12-14 18:04:29,785: INFO: helpers: Accessing as saivardhan4694]
[2024-12-14 18:04:30,286: INFO: _client: HTTP Request: GET https://dagshub.com/api/v1/repos/saivardhan4694/coustomer_churn_prediction_system "HTTP/1.1 200 OK"]
[2024-12-14 18:04:30,779: INFO: _client: HTTP Request: GET https://dagshub.com/api/v1/user "HTTP/1.1 200 OK"]
[2024-12-14 18:04:30,780: INFO: helpers: Initialized MLflow to track repo "saivardhan4694/coustomer_churn_prediction_system"]
[2024-12-14 18:04:30,780: INFO: helpers: Repository saivardhan4694/coustomer_churn_prediction_system initialized!]
[2024-12-14 18:04:34,977: INFO: common: Directory prediction_artifacts/data_validation created successfully]
[2024-12-14 18:04:34,980: INFO: validator: Schema Validation Passed: Column names, data types, and constraints match expectations.]
[2024-12-14 18:05:38,993: INFO: common: yaml file: D:\repositories\coustomer_churn_prediction_system\config\prediction_config.yaml loaded successfully]
[2024-12-14 18:05:38,993: INFO: common: Directory prediction_artifacts created successfully]
[2024-12-14 18:05:39,502: INFO: _client: HTTP Request: GET https://dagshub.com/api/v1/user "HTTP/1.1 200 OK"]
[2024-12-14 18:05:39,507: INFO: helpers: Accessing as saivardhan4694]
[2024-12-14 18:05:40,003: INFO: _client: HTTP Request: GET https://dagshub.com/api/v1/repos/saivardhan4694/coustomer_churn_prediction_system "HTTP/1.1 200 OK"]
[2024-12-14 18:05:40,486: INFO: _client: HTTP Request: GET https://dagshub.com/api/v1/user "HTTP/1.1 200 OK"]
[2024-12-14 18:05:40,486: INFO: helpers: Initialized MLflow to track repo "saivardhan4694/coustomer_churn_prediction_system"]
[2024-12-14 18:05:40,502: INFO: helpers: Repository saivardhan4694/coustomer_churn_prediction_system initialized!]
[2024-12-14 18:05:44,385: INFO: common: Directory prediction_artifacts/data_validation created successfully]
[2024-12-14 18:05:44,391: INFO: validator: Schema Validation Passed: Column names, data types, and constraints match expectations.]
[2024-12-14 18:11:02,348: INFO: common: yaml file: D:\repositories\coustomer_churn_prediction_system\config\prediction_config.yaml loaded successfully]
[2024-12-14 18:11:02,348: INFO: common: Directory prediction_artifacts created successfully]
[2024-12-14 18:11:02,861: INFO: _client: HTTP Request: GET https://dagshub.com/api/v1/user "HTTP/1.1 200 OK"]
[2024-12-14 18:11:02,862: INFO: helpers: Accessing as saivardhan4694]
[2024-12-14 18:11:03,394: INFO: _client: HTTP Request: GET https://dagshub.com/api/v1/repos/saivardhan4694/coustomer_churn_prediction_system "HTTP/1.1 200 OK"]
[2024-12-14 18:11:03,877: INFO: _client: HTTP Request: GET https://dagshub.com/api/v1/user "HTTP/1.1 200 OK"]
[2024-12-14 18:11:03,893: INFO: helpers: Initialized MLflow to track repo "saivardhan4694/coustomer_churn_prediction_system"]
[2024-12-14 18:11:03,893: INFO: helpers: Repository saivardhan4694/coustomer_churn_prediction_system initialized!]
[2024-12-14 18:11:08,353: INFO: common: Directory prediction_artifacts/data_validation created successfully]
[2024-12-14 18:11:08,358: INFO: validator: Schema Validation Passed: Column names, data types, and constraints match expectations.]
[2024-12-14 18:18:22,046: INFO: common: yaml file: D:\repositories\coustomer_churn_prediction_system\config\prediction_config.yaml loaded successfully]
[2024-12-14 18:18:22,048: INFO: common: Directory prediction_artifacts created successfully]
[2024-12-14 18:18:25,124: INFO: common: yaml file: D:\repositories\coustomer_churn_prediction_system\config\prediction_config.yaml loaded successfully]
[2024-12-14 18:18:25,126: INFO: common: Directory prediction_artifacts created successfully]
[2024-12-14 18:18:25,917: INFO: _client: HTTP Request: GET https://dagshub.com/api/v1/user "HTTP/1.1 200 OK"]
[2024-12-14 18:18:25,923: INFO: helpers: Accessing as saivardhan4694]
[2024-12-14 18:18:26,510: INFO: _client: HTTP Request: GET https://dagshub.com/api/v1/repos/saivardhan4694/coustomer_churn_prediction_system "HTTP/1.1 200 OK"]
[2024-12-14 18:18:27,065: INFO: _client: HTTP Request: GET https://dagshub.com/api/v1/user "HTTP/1.1 200 OK"]
[2024-12-14 18:18:27,065: INFO: helpers: Initialized MLflow to track repo "saivardhan4694/coustomer_churn_prediction_system"]
[2024-12-14 18:18:27,065: INFO: helpers: Repository saivardhan4694/coustomer_churn_prediction_system initialized!]
[2024-12-14 18:18:31,265: INFO: common: Directory prediction_artifacts/data_validation created successfully]
[2024-12-14 18:18:31,269: INFO: validator: Schema Validation Passed: Column names, data types, and constraints match expectations.]
[2024-12-14 18:19:07,392: INFO: common: yaml file: D:\repositories\coustomer_churn_prediction_system\config\prediction_config.yaml loaded successfully]
[2024-12-14 18:19:07,394: INFO: common: Directory prediction_artifacts created successfully]
[2024-12-14 18:29:16,204: INFO: common: yaml file: D:\repositories\coustomer_churn_prediction_system\config\prediction_config.yaml loaded successfully]
[2024-12-14 18:29:16,205: INFO: common: Directory prediction_artifacts created successfully]
[2024-12-14 18:29:20,450: INFO: common: yaml file: D:\repositories\coustomer_churn_prediction_system\config\prediction_config.yaml loaded successfully]
[2024-12-14 18:29:20,452: INFO: common: Directory prediction_artifacts created successfully]
[2024-12-14 18:29:21,188: INFO: _client: HTTP Request: GET https://dagshub.com/api/v1/repos/saivardhan4694/coustomer_churn_prediction_system "HTTP/1.1 200 OK"]
[2024-12-14 18:29:21,204: INFO: helpers: Initialized MLflow to track repo "saivardhan4694/coustomer_churn_prediction_system"]
[2024-12-14 18:29:21,204: INFO: helpers: Repository saivardhan4694/coustomer_churn_prediction_system initialized!]
[2024-12-14 18:29:21,224: WARNING: connectionpool: Retrying (Retry(total=4, connect=5, read=4, redirect=5, status=5)) after connection broken by 'RemoteDisconnected('Remote end closed connection without response')': /saivardhan4694/coustomer_churn_prediction_system.mlflow/api/2.0/mlflow/registered-models/get-latest-versions]
[2024-12-14 18:29:22,852: WARNING: connectionpool: Retrying (Retry(total=4, connect=5, read=4, redirect=5, status=5)) after connection broken by 'RemoteDisconnected('Remote end closed connection without response')': /saivardhan4694/coustomer_churn_prediction_system.mlflow/api/2.0/mlflow-artifacts/artifacts/81805038eee24f3cbcf0e9d447ff2a58/a210da2aa7764364a209764ca6b3f1fe/artifacts/ensemble_model/MLmodel]
[2024-12-14 18:29:22,854: WARNING: connectionpool: Retrying (Retry(total=4, connect=5, read=4, redirect=5, status=5)) after connection broken by 'RemoteDisconnected('Remote end closed connection without response')': /saivardhan4694/coustomer_churn_prediction_system.mlflow/api/2.0/mlflow-artifacts/artifacts/81805038eee24f3cbcf0e9d447ff2a58/a210da2aa7764364a209764ca6b3f1fe/artifacts/ensemble_model/python_env.yaml]
[2024-12-14 18:29:22,857: WARNING: connectionpool: Retrying (Retry(total=4, connect=5, read=4, redirect=5, status=5)) after connection broken by 'RemoteDisconnected('Remote end closed connection without response')': /saivardhan4694/coustomer_churn_prediction_system.mlflow/api/2.0/mlflow-artifacts/artifacts/81805038eee24f3cbcf0e9d447ff2a58/a210da2aa7764364a209764ca6b3f1fe/artifacts/ensemble_model/model.pkl]
[2024-12-14 18:29:22,857: WARNING: connectionpool: Retrying (Retry(total=4, connect=5, read=4, redirect=5, status=5)) after connection broken by 'RemoteDisconnected('Remote end closed connection without response')': /saivardhan4694/coustomer_churn_prediction_system.mlflow/api/2.0/mlflow-artifacts/artifacts/81805038eee24f3cbcf0e9d447ff2a58/a210da2aa7764364a209764ca6b3f1fe/artifacts/ensemble_model/requirements.txt]
[2024-12-14 18:29:25,295: INFO: common: Directory prediction_artifacts/data_validation created successfully]
[2024-12-14 18:29:25,300: INFO: validator: Schema Validation Passed: Column names, data types, and constraints match expectations.]
[2024-12-14 18:32:56,723: INFO: common: yaml file: D:\repositories\coustomer_churn_prediction_system\config\prediction_config.yaml loaded successfully]
[2024-12-14 18:32:56,725: INFO: common: Directory prediction_artifacts created successfully]
[2024-12-14 18:32:59,543: INFO: common: yaml file: D:\repositories\coustomer_churn_prediction_system\config\prediction_config.yaml loaded successfully]
[2024-12-14 18:32:59,543: INFO: common: Directory prediction_artifacts created successfully]
[2024-12-14 18:33:00,162: INFO: _client: HTTP Request: GET https://dagshub.com/api/v1/repos/saivardhan4694/coustomer_churn_prediction_system "HTTP/1.1 200 OK"]
[2024-12-14 18:33:00,164: INFO: helpers: Initialized MLflow to track repo "saivardhan4694/coustomer_churn_prediction_system"]
[2024-12-14 18:33:00,166: INFO: helpers: Repository saivardhan4694/coustomer_churn_prediction_system initialized!]
[2024-12-14 18:33:04,169: INFO: common: Directory prediction_artifacts/data_validation created successfully]
[2024-12-14 18:33:04,175: INFO: validator: Schema Validation Passed: Column names, data types, and constraints match expectations.]
[2024-12-14 19:19:14,000: INFO: _client: HTTP Request: GET https://dagshub.com/api/v1/user "HTTP/1.1 200 OK"]
[2024-12-14 19:19:14,000: INFO: helpers: Accessing as saivardhan4694]
[2024-12-14 19:19:14,507: INFO: _client: HTTP Request: GET https://dagshub.com/api/v1/repos/saivardhan4694/coustomer_churn_prediction_system "HTTP/1.1 200 OK"]
[2024-12-14 19:19:15,001: INFO: _client: HTTP Request: GET https://dagshub.com/api/v1/user "HTTP/1.1 200 OK"]
[2024-12-14 19:19:15,007: INFO: helpers: Initialized MLflow to track repo "saivardhan4694/coustomer_churn_prediction_system"]
[2024-12-14 19:19:15,007: INFO: helpers: Repository saivardhan4694/coustomer_churn_prediction_system initialized!]
